<sdf version='1.7'>
  <model name='polysat'>
    <link name='polysat/base_link'>
      <inertial>
        <pose>1e-06 0 2e-06 0 -0 0</pose>
        <mass>50.0002</mass>
        <inertia>
          <ixx>10.0001</ixx>
          <ixy>-1.70999e-06</ixy>
          <ixz>-3.23249e-05</ixz>
          <iyy>10.0001</iyy>
          <iyz>-5.32498e-06</iyz>
          <izz>10</izz>
        </inertia>
      </inertial>
      <collision name='polysat/base_link_fixed_joint_lump__polysat/polysat_link_collision'>
        <pose>-0.5 1 -0.5 1.5708 -0 0</pose>
        <geometry>
          <mesh>
            <scale>0.001 0.001 0.001</scale>
            <uri>file:///home/carson/spaceship_ws/src/spacecraft_sim/urdf/robots/polysat_description/meshes/base.stl</uri>
          </mesh>
        </geometry>
      </collision>
      <collision name='polysat/base_link_fixed_joint_lump__polysat/thrust_plume_0_visual_collision_1'>
        <pose>0.265 0.165 0.55 1.5708 -0 0</pose>
        <geometry>
          <mesh>
            <scale>0.001 0.001 0.001</scale>
            <uri>file:///home/carson/spaceship_ws/src/spacecraft_sim/urdf/robots/polysat_description/meshes/thrust_plume.stl</uri>
          </mesh>
        </geometry>
      </collision>
      <collision name='polysat/base_link_fixed_joint_lump__polysat/thruster_0_visual_collision_2'>
        <pose>0.355 -0.075 0.5 0 -0 0</pose>
        <geometry>
          <mesh>
            <scale>0.001 0.001 0.001</scale>
            <uri>file:///home/carson/spaceship_ws/src/spacecraft_sim/urdf/robots/polysat_description/meshes/thruster.stl</uri>
          </mesh>
        </geometry>
      </collision>
      <visual name='polysat/base_link_fixed_joint_lump__polysat/polysat_link_visual'>
        <pose>-0.5 1 -0.5 1.5708 -0 0</pose>
        <geometry>
          <mesh>
            <scale>0.001 0.001 0.001</scale>
            <uri>file:///home/carson/spaceship_ws/src/spacecraft_sim/urdf/robots/polysat_description/meshes/base.stl</uri>
          </mesh>
        </geometry>
      </visual>
      <visual name='polysat/base_link_fixed_joint_lump__polysat/thrust_plume_0_visual_visual_1'>
				<plugin filename= "libsc_thrust_visual_plugin.so" name="thrust_visual"> 
					<thrust_color>1 0 0 1</thrust_color> 
				</plugin>
        <pose>0.265 0.165 0.55 1.5708 -0 0</pose>
        <geometry>
          <mesh>
            <scale>0.001 0.001 0.001</scale>
            <uri>file:///home/carson/spaceship_ws/src/spacecraft_sim/urdf/robots/polysat_description/meshes/thrust_plume.stl</uri>
          </mesh>
        </geometry>
      </visual>
      <visual name='polysat/base_link_fixed_joint_lump__polysat/thruster_0_visual_visual_2'>
        <pose>0.355 -0.075 0.5 0 -0 0</pose>
        <geometry>
          <mesh>
            <scale>0.001 0.001 0.001</scale>
            <uri>file:///home/carson/spaceship_ws/src/spacecraft_sim/urdf/robots/polysat_description/meshes/thruster.stl</uri>
          </mesh>
        </geometry>
        <!-- plugin filename="libsc_led_visual_plugin.so" name="blink">
          <color_a>1 0 0 1</color_a>
          <color_b>1 0 0 0</color_b>
          <period>1</period>
        </plugin-->
        <plugin filename="libsc_thrust_visual_plugin.so" name="thrust_visual">
          <thrust_color>1 0 0 1</thrust_color>
        </plugin>
      </visual>
    </link>
    <joint name='polysat/imu_joint' type='revolute'>
      <pose relative_to='polysat/base_link'>0 0 0 0 -0 0</pose>
      <parent>polysat/base_link</parent>
      <child>polysat/imu_link</child>
      <axis>
        <xyz>1 0 0</xyz>
        <limit>
          <lower>0</lower>
          <upper>0</upper>
          <effort>0</effort>
          <velocity>0</velocity>
        </limit>
        <dynamics>
          <spring_reference>0</spring_reference>
          <spring_stiffness>0</spring_stiffness>
        </dynamics>
      </axis>
    </joint>
    <link name='polysat/imu_link'>
      <pose relative_to='polysat/imu_joint'>0 0 0 0 -0 0</pose>
      <inertial>
        <pose>0 0 0 0 -0 0</pose>
        <mass>0.015</mass>
        <inertia>
          <ixx>1e-05</ixx>
          <ixy>0</ixy>
          <ixz>0</ixz>
          <iyy>1e-05</iyy>
          <iyz>0</iyz>
          <izz>1e-05</izz>
        </inertia>
      </inertial>
    </link>
    <joint name='polysat/pose_sensor_default_joint' type='revolute'>
      <pose relative_to='polysat/base_link'>0 0 0 0 -0 0</pose>
      <parent>polysat/base_link</parent>
      <child>polysat/pose_sensor_link_default</child>
      <axis>
        <xyz>0 0 1</xyz>
        <limit>
          <lower>0</lower>
          <upper>0</upper>
          <effort>0</effort>
          <velocity>0</velocity>
        </limit>
        <dynamics>
          <spring_reference>0</spring_reference>
          <spring_stiffness>0</spring_stiffness>
        </dynamics>
      </axis>
    </joint>
    <link name='polysat/pose_sensor_link_default'>
      <pose relative_to='polysat/pose_sensor_default_joint'>0 0 0 0 -0 0</pose>
      <inertial>
        <pose>0 0 0 0 -0 0</pose>
        <mass>0.001</mass>
        <inertia>
          <ixx>1e-05</ixx>
          <ixy>0</ixy>
          <ixz>0</ixz>
          <iyy>1e-05</iyy>
          <iyz>0</iyz>
          <izz>1e-05</izz>
        </inertia>
      </inertial>
    </link>
    <joint name='polysat/thruster_0_joint' type='revolute'>
      <pose relative_to='polysat/base_link'>0.5 0 0.5 0 -0 0</pose>
      <parent>polysat/base_link</parent>
      <child>polysat/thruster_0</child>
      <axis>
        <xyz>1 0 0</xyz>
        <limit>
          <effort>0</effort>
          <velocity>0</velocity>
          <lower>-1e+16</lower>
          <upper>1e+16</upper>
        </limit>
        <dynamics>
          <spring_reference>0</spring_reference>
          <spring_stiffness>0</spring_stiffness>
        </dynamics>
      </axis>
    </joint>
    <link name='polysat/thruster_0'>
      <pose relative_to='polysat/thruster_0_joint'>0 0 0 0 -0 0</pose>
      <inertial>
        <pose>0 0 0 0 -0 0</pose>
        <mass>0.0001</mass>
        <inertia>
          <ixx>1.66667e-11</ixx>
          <ixy>0</ixy>
          <ixz>0</ixz>
          <iyy>1.66667e-11</iyy>
          <iyz>0</iyz>
          <izz>1.66667e-11</izz>
        </inertia>
      </inertial>
      <collision name='polysat/thruster_0_collision'>
        <pose>0 0 0 0 -0 0</pose>
        <geometry>
          <cylinder>
            <length>1e-07</length>
            <radius>1e-07</radius>
          </cylinder>
        </geometry>
        <surface>
          <contact>
            <ode/>
          </contact>
          <friction>
            <ode/>
          </friction>
        </surface>
      </collision>
      <visual name='polysat/thruster_0_visual'>
        <pose>0 0 0 0 -0 0</pose>
        <geometry>
          <cylinder>
            <length>1e-06</length>
            <radius>1e-07</radius>
          </cylinder>
        </geometry>
      </visual>
      <self_collide>0</self_collide>
    </link>
    <joint name='polysat/thruster_10_joint' type='revolute'>
      <pose relative_to='polysat/base_link'>-0.5 0.5 0 0 -0 3.14159</pose>
      <parent>polysat/base_link</parent>
      <child>polysat/thruster_10</child>
      <axis>
        <xyz>1 0 0</xyz>
        <limit>
          <effort>0</effort>
          <velocity>0</velocity>
          <lower>-1e+16</lower>
          <upper>1e+16</upper>
        </limit>
        <dynamics>
          <spring_reference>0</spring_reference>
          <spring_stiffness>0</spring_stiffness>
        </dynamics>
      </axis>
    </joint>
    <link name='polysat/thruster_10'>
      <pose relative_to='polysat/thruster_10_joint'>0 0 0 0 -0 0</pose>
      <inertial>
        <pose>0 0 0 0 -0 0</pose>
        <mass>0.0001</mass>
        <inertia>
          <ixx>1.66667e-11</ixx>
          <ixy>0</ixy>
          <ixz>0</ixz>
          <iyy>1.66667e-11</iyy>
          <iyz>0</iyz>
          <izz>1.66667e-11</izz>
        </inertia>
      </inertial>
      <collision name='polysat/thruster_10_collision'>
        <pose>0 0 0 0 -0 0</pose>
        <geometry>
          <cylinder>
            <length>1e-07</length>
            <radius>1e-07</radius>
          </cylinder>
        </geometry>
        <surface>
          <contact>
            <ode/>
          </contact>
          <friction>
            <ode/>
          </friction>
        </surface>
      </collision>
      <visual name='polysat/thruster_10_visual'>
        <pose>0 0 0 0 -0 0</pose>
        <geometry>
          <cylinder>
            <length>1e-06</length>
            <radius>1e-07</radius>
          </cylinder>
        </geometry>
      </visual>
      <self_collide>0</self_collide>
    </link>
    <joint name='polysat/thruster_11_joint' type='revolute'>
      <pose relative_to='polysat/base_link'>-0.5 -0.5 0 0 -0 3.14159</pose>
      <parent>polysat/base_link</parent>
      <child>polysat/thruster_11</child>
      <axis>
        <xyz>1 0 0</xyz>
        <limit>
          <effort>0</effort>
          <velocity>0</velocity>
          <lower>-1e+16</lower>
          <upper>1e+16</upper>
        </limit>
        <dynamics>
          <spring_reference>0</spring_reference>
          <spring_stiffness>0</spring_stiffness>
        </dynamics>
      </axis>
    </joint>
    <link name='polysat/thruster_11'>
      <pose relative_to='polysat/thruster_11_joint'>0 0 0 0 -0 0</pose>
      <inertial>
        <pose>0 0 0 0 -0 0</pose>
        <mass>0.0001</mass>
        <inertia>
          <ixx>1.66667e-11</ixx>
          <ixy>0</ixy>
          <ixz>0</ixz>
          <iyy>1.66667e-11</iyy>
          <iyz>0</iyz>
          <izz>1.66667e-11</izz>
        </inertia>
      </inertial>
      <collision name='polysat/thruster_11_collision'>
        <pose>0 0 0 0 -0 0</pose>
        <geometry>
          <cylinder>
            <length>1e-07</length>
            <radius>1e-07</radius>
          </cylinder>
        </geometry>
        <surface>
          <contact>
            <ode/>
          </contact>
          <friction>
            <ode/>
          </friction>
        </surface>
      </collision>
      <visual name='polysat/thruster_11_visual'>
        <pose>0 0 0 0 -0 0</pose>
        <geometry>
          <cylinder>
            <length>1e-06</length>
            <radius>1e-07</radius>
          </cylinder>
        </geometry>
      </visual>
      <self_collide>0</self_collide>
    </link>
    <joint name='polysat/thruster_12_joint' type='revolute'>
      <pose relative_to='polysat/base_link'>0 0.5 0 0 -0 1.5708</pose>
      <parent>polysat/base_link</parent>
      <child>polysat/thruster_12</child>
      <axis>
        <xyz>1 0 0</xyz>
        <limit>
          <effort>0</effort>
          <velocity>0</velocity>
          <lower>-1e+16</lower>
          <upper>1e+16</upper>
        </limit>
        <dynamics>
          <spring_reference>0</spring_reference>
          <spring_stiffness>0</spring_stiffness>
        </dynamics>
      </axis>
    </joint>
    <link name='polysat/thruster_12'>
      <pose relative_to='polysat/thruster_12_joint'>0 0 0 0 -0 0</pose>
      <inertial>
        <pose>0 0 0 0 -0 0</pose>
        <mass>0.0001</mass>
        <inertia>
          <ixx>1.66667e-11</ixx>
          <ixy>0</ixy>
          <ixz>0</ixz>
          <iyy>1.66667e-11</iyy>
          <iyz>0</iyz>
          <izz>1.66667e-11</izz>
        </inertia>
      </inertial>
      <collision name='polysat/thruster_12_collision'>
        <pose>0 0 0 0 -0 0</pose>
        <geometry>
          <cylinder>
            <length>1e-07</length>
            <radius>1e-07</radius>
          </cylinder>
        </geometry>
        <surface>
          <contact>
            <ode/>
          </contact>
          <friction>
            <ode/>
          </friction>
        </surface>
      </collision>
      <visual name='polysat/thruster_12_visual'>
        <pose>0 0 0 0 -0 0</pose>
        <geometry>
          <cylinder>
            <length>1e-06</length>
            <radius>1e-07</radius>
          </cylinder>
        </geometry>
      </visual>
      <self_collide>0</self_collide>
    </link>
    <joint name='polysat/thruster_13_joint' type='revolute'>
      <pose relative_to='polysat/base_link'>0 -0.5 0 0 0 -1.5708</pose>
      <parent>polysat/base_link</parent>
      <child>polysat/thruster_13</child>
      <axis>
        <xyz>1 0 0</xyz>
        <limit>
          <effort>0</effort>
          <velocity>0</velocity>
          <lower>-1e+16</lower>
          <upper>1e+16</upper>
        </limit>
        <dynamics>
          <spring_reference>0</spring_reference>
          <spring_stiffness>0</spring_stiffness>
        </dynamics>
      </axis>
    </joint>
    <link name='polysat/thruster_13'>
      <pose relative_to='polysat/thruster_13_joint'>0 0 0 0 -0 0</pose>
      <inertial>
        <pose>0 0 0 0 -0 0</pose>
        <mass>0.0001</mass>
        <inertia>
          <ixx>1.66667e-11</ixx>
          <ixy>0</ixy>
          <ixz>0</ixz>
          <iyy>1.66667e-11</iyy>
          <iyz>0</iyz>
          <izz>1.66667e-11</izz>
        </inertia>
      </inertial>
      <collision name='polysat/thruster_13_collision'>
        <pose>0 0 0 0 -0 0</pose>
        <geometry>
          <cylinder>
            <length>1e-07</length>
            <radius>1e-07</radius>
          </cylinder>
        </geometry>
        <surface>
          <contact>
            <ode/>
          </contact>
          <friction>
            <ode/>
          </friction>
        </surface>
      </collision>
      <visual name='polysat/thruster_13_visual'>
        <pose>0 0 0 0 -0 0</pose>
        <geometry>
          <cylinder>
            <length>1e-06</length>
            <radius>1e-07</radius>
          </cylinder>
        </geometry>
      </visual>
      <self_collide>0</self_collide>
    </link>
    <joint name='polysat/thruster_1_joint' type='revolute'>
      <pose relative_to='polysat/base_link'>0.5 0 -0.5 0 -0 0</pose>
      <parent>polysat/base_link</parent>
      <child>polysat/thruster_1</child>
      <axis>
        <xyz>1 0 0</xyz>
        <limit>
          <effort>0</effort>
          <velocity>0</velocity>
          <lower>-1e+16</lower>
          <upper>1e+16</upper>
        </limit>
        <dynamics>
          <spring_reference>0</spring_reference>
          <spring_stiffness>0</spring_stiffness>
        </dynamics>
      </axis>
    </joint>
    <link name='polysat/thruster_1'>
      <pose relative_to='polysat/thruster_1_joint'>0 0 0 0 -0 0</pose>
      <inertial>
        <pose>0 0 0 0 -0 0</pose>
        <mass>0.0001</mass>
        <inertia>
          <ixx>1.66667e-11</ixx>
          <ixy>0</ixy>
          <ixz>0</ixz>
          <iyy>1.66667e-11</iyy>
          <iyz>0</iyz>
          <izz>1.66667e-11</izz>
        </inertia>
      </inertial>
      <collision name='polysat/thruster_1_collision'>
        <pose>0 0 0 0 -0 0</pose>
        <geometry>
          <cylinder>
            <length>1e-07</length>
            <radius>1e-07</radius>
          </cylinder>
        </geometry>
        <surface>
          <contact>
            <ode/>
          </contact>
          <friction>
            <ode/>
          </friction>
        </surface>
      </collision>
      <visual name='polysat/thruster_1_visual'>
        <pose>0 0 0 0 -0 0</pose>
        <geometry>
          <cylinder>
            <length>1e-06</length>
            <radius>1e-07</radius>
          </cylinder>
        </geometry>
      </visual>
      <self_collide>0</self_collide>
    </link>
    <joint name='polysat/thruster_2_joint' type='revolute'>
      <pose relative_to='polysat/base_link'>-0.5 0 0.5 0 -0 3.14159</pose>
      <parent>polysat/base_link</parent>
      <child>polysat/thruster_2</child>
      <axis>
        <xyz>1 0 0</xyz>
        <limit>
          <effort>0</effort>
          <velocity>0</velocity>
          <lower>-1e+16</lower>
          <upper>1e+16</upper>
        </limit>
        <dynamics>
          <spring_reference>0</spring_reference>
          <spring_stiffness>0</spring_stiffness>
        </dynamics>
      </axis>
    </joint>
    <link name='polysat/thruster_2'>
      <pose relative_to='polysat/thruster_2_joint'>0 0 0 0 -0 0</pose>
      <inertial>
        <pose>0 0 0 0 -0 0</pose>
        <mass>0.0001</mass>
        <inertia>
          <ixx>1.66667e-11</ixx>
          <ixy>0</ixy>
          <ixz>0</ixz>
          <iyy>1.66667e-11</iyy>
          <iyz>0</iyz>
          <izz>1.66667e-11</izz>
        </inertia>
      </inertial>
      <collision name='polysat/thruster_2_collision'>
        <pose>0 0 0 0 -0 0</pose>
        <geometry>
          <cylinder>
            <length>1e-07</length>
            <radius>1e-07</radius>
          </cylinder>
        </geometry>
        <surface>
          <contact>
            <ode/>
          </contact>
          <friction>
            <ode/>
          </friction>
        </surface>
      </collision>
      <visual name='polysat/thruster_2_visual'>
        <pose>0 0 0 0 -0 0</pose>
        <geometry>
          <cylinder>
            <length>1e-06</length>
            <radius>1e-07</radius>
          </cylinder>
        </geometry>
      </visual>
      <self_collide>0</self_collide>
    </link>
    <joint name='polysat/thruster_3_joint' type='revolute'>
      <pose relative_to='polysat/base_link'>-0.5 0 -0.5 0 -0 3.14159</pose>
      <parent>polysat/base_link</parent>
      <child>polysat/thruster_3</child>
      <axis>
        <xyz>1 0 0</xyz>
        <limit>
          <effort>0</effort>
          <velocity>0</velocity>
          <lower>-1e+16</lower>
          <upper>1e+16</upper>
        </limit>
        <dynamics>
          <spring_reference>0</spring_reference>
          <spring_stiffness>0</spring_stiffness>
        </dynamics>
      </axis>
    </joint>
    <link name='polysat/thruster_3'>
      <pose relative_to='polysat/thruster_3_joint'>0 0 0 0 -0 0</pose>
      <inertial>
        <pose>0 0 0 0 -0 0</pose>
        <mass>0.0001</mass>
        <inertia>
          <ixx>1.66667e-11</ixx>
          <ixy>0</ixy>
          <ixz>0</ixz>
          <iyy>1.66667e-11</iyy>
          <iyz>0</iyz>
          <izz>1.66667e-11</izz>
        </inertia>
      </inertial>
      <collision name='polysat/thruster_3_collision'>
        <pose>0 0 0 0 -0 0</pose>
        <geometry>
          <cylinder>
            <length>1e-07</length>
            <radius>1e-07</radius>
          </cylinder>
        </geometry>
        <surface>
          <contact>
            <ode/>
          </contact>
          <friction>
            <ode/>
          </friction>
        </surface>
      </collision>
      <visual name='polysat/thruster_3_visual'>
        <pose>0 0 0 0 -0 0</pose>
        <geometry>
          <cylinder>
            <length>1e-06</length>
            <radius>1e-07</radius>
          </cylinder>
        </geometry>
      </visual>
      <self_collide>0</self_collide>
    </link>
    <joint name='polysat/thruster_4_joint' type='revolute'>
      <pose relative_to='polysat/base_link'>0 0.5 0.5 0 -1.5708 0</pose>
      <parent>polysat/base_link</parent>
      <child>polysat/thruster_4</child>
      <axis>
        <xyz>1 0 0</xyz>
        <limit>
          <effort>0</effort>
          <velocity>0</velocity>
          <lower>-1e+16</lower>
          <upper>1e+16</upper>
        </limit>
        <dynamics>
          <spring_reference>0</spring_reference>
          <spring_stiffness>0</spring_stiffness>
        </dynamics>
      </axis>
    </joint>
    <link name='polysat/thruster_4'>
      <pose relative_to='polysat/thruster_4_joint'>0 0 0 0 -0 0</pose>
      <inertial>
        <pose>0 0 0 0 -0 0</pose>
        <mass>0.0001</mass>
        <inertia>
          <ixx>1.66667e-11</ixx>
          <ixy>0</ixy>
          <ixz>0</ixz>
          <iyy>1.66667e-11</iyy>
          <iyz>0</iyz>
          <izz>1.66667e-11</izz>
        </inertia>
      </inertial>
      <collision name='polysat/thruster_4_collision'>
        <pose>0 0 0 0 -0 0</pose>
        <geometry>
          <cylinder>
            <length>1e-07</length>
            <radius>1e-07</radius>
          </cylinder>
        </geometry>
        <surface>
          <contact>
            <ode/>
          </contact>
          <friction>
            <ode/>
          </friction>
        </surface>
      </collision>
      <visual name='polysat/thruster_4_visual'>
        <pose>0 0 0 0 -0 0</pose>
        <geometry>
          <cylinder>
            <length>1e-06</length>
            <radius>1e-07</radius>
          </cylinder>
        </geometry>
      </visual>
      <self_collide>0</self_collide>
    </link>
    <joint name='polysat/thruster_5_joint' type='revolute'>
      <pose relative_to='polysat/base_link'>0 -0.5 0.5 0 -1.5708 0</pose>
      <parent>polysat/base_link</parent>
      <child>polysat/thruster_5</child>
      <axis>
        <xyz>1 0 0</xyz>
        <limit>
          <effort>0</effort>
          <velocity>0</velocity>
          <lower>-1e+16</lower>
          <upper>1e+16</upper>
        </limit>
        <dynamics>
          <spring_reference>0</spring_reference>
          <spring_stiffness>0</spring_stiffness>
        </dynamics>
      </axis>
    </joint>
    <link name='polysat/thruster_5'>
      <pose relative_to='polysat/thruster_5_joint'>0 0 0 0 -0 0</pose>
      <inertial>
        <pose>0 0 0 0 -0 0</pose>
        <mass>0.0001</mass>
        <inertia>
          <ixx>1.66667e-11</ixx>
          <ixy>0</ixy>
          <ixz>0</ixz>
          <iyy>1.66667e-11</iyy>
          <iyz>0</iyz>
          <izz>1.66667e-11</izz>
        </inertia>
      </inertial>
      <collision name='polysat/thruster_5_collision'>
        <pose>0 0 0 0 -0 0</pose>
        <geometry>
          <cylinder>
            <length>1e-07</length>
            <radius>1e-07</radius>
          </cylinder>
        </geometry>
        <surface>
          <contact>
            <ode/>
          </contact>
          <friction>
            <ode/>
          </friction>
        </surface>
      </collision>
      <visual name='polysat/thruster_5_visual'>
        <pose>0 0 0 0 -0 0</pose>
        <geometry>
          <cylinder>
            <length>1e-06</length>
            <radius>1e-07</radius>
          </cylinder>
        </geometry>
      </visual>
      <self_collide>0</self_collide>
    </link>
    <joint name='polysat/thruster_6_joint' type='revolute'>
      <pose relative_to='polysat/base_link'>0 0.5 -0.5 0 1.5708 0</pose>
      <parent>polysat/base_link</parent>
      <child>polysat/thruster_6</child>
      <axis>
        <xyz>1 0 0</xyz>
        <limit>
          <effort>0</effort>
          <velocity>0</velocity>
          <lower>-1e+16</lower>
          <upper>1e+16</upper>
        </limit>
        <dynamics>
          <spring_reference>0</spring_reference>
          <spring_stiffness>0</spring_stiffness>
        </dynamics>
      </axis>
    </joint>
    <link name='polysat/thruster_6'>
      <pose relative_to='polysat/thruster_6_joint'>0 0 0 0 -0 0</pose>
      <inertial>
        <pose>0 0 0 0 -0 0</pose>
        <mass>0.0001</mass>
        <inertia>
          <ixx>1.66667e-11</ixx>
          <ixy>0</ixy>
          <ixz>0</ixz>
          <iyy>1.66667e-11</iyy>
          <iyz>0</iyz>
          <izz>1.66667e-11</izz>
        </inertia>
      </inertial>
      <collision name='polysat/thruster_6_collision'>
        <pose>0 0 0 0 -0 0</pose>
        <geometry>
          <cylinder>
            <length>1e-07</length>
            <radius>1e-07</radius>
          </cylinder>
        </geometry>
        <surface>
          <contact>
            <ode/>
          </contact>
          <friction>
            <ode/>
          </friction>
        </surface>
      </collision>
      <visual name='polysat/thruster_6_visual'>
        <pose>0 0 0 0 -0 0</pose>
        <geometry>
          <cylinder>
            <length>1e-06</length>
            <radius>1e-07</radius>
          </cylinder>
        </geometry>
      </visual>
      <self_collide>0</self_collide>
    </link>
    <joint name='polysat/thruster_7_joint' type='revolute'>
      <pose relative_to='polysat/base_link'>0 -0.5 -0.5 0 1.5708 0</pose>
      <parent>polysat/base_link</parent>
      <child>polysat/thruster_7</child>
      <axis>
        <xyz>1 0 0</xyz>
        <limit>
          <effort>0</effort>
          <velocity>0</velocity>
          <lower>-1e+16</lower>
          <upper>1e+16</upper>
        </limit>
        <dynamics>
          <spring_reference>0</spring_reference>
          <spring_stiffness>0</spring_stiffness>
        </dynamics>
      </axis>
    </joint>
    <link name='polysat/thruster_7'>
      <pose relative_to='polysat/thruster_7_joint'>0 0 0 0 -0 0</pose>
      <inertial>
        <pose>0 0 0 0 -0 0</pose>
        <mass>0.0001</mass>
        <inertia>
          <ixx>1.66667e-11</ixx>
          <ixy>0</ixy>
          <ixz>0</ixz>
          <iyy>1.66667e-11</iyy>
          <iyz>0</iyz>
          <izz>1.66667e-11</izz>
        </inertia>
      </inertial>
      <collision name='polysat/thruster_7_collision'>
        <pose>0 0 0 0 -0 0</pose>
        <geometry>
          <cylinder>
            <length>1e-07</length>
            <radius>1e-07</radius>
          </cylinder>
        </geometry>
        <surface>
          <contact>
            <ode/>
          </contact>
          <friction>
            <ode/>
          </friction>
        </surface>
      </collision>
      <visual name='polysat/thruster_7_visual'>
        <pose>0 0 0 0 -0 0</pose>
        <geometry>
          <cylinder>
            <length>1e-06</length>
            <radius>1e-07</radius>
          </cylinder>
        </geometry>
      </visual>
      <self_collide>0</self_collide>
    </link>
    <joint name='polysat/thruster_8_joint' type='revolute'>
      <pose relative_to='polysat/base_link'>0.5 0.5 0 0 -0 0</pose>
      <parent>polysat/base_link</parent>
      <child>polysat/thruster_8</child>
      <axis>
        <xyz>1 0 0</xyz>
        <limit>
          <effort>0</effort>
          <velocity>0</velocity>
          <lower>-1e+16</lower>
          <upper>1e+16</upper>
        </limit>
        <dynamics>
          <spring_reference>0</spring_reference>
          <spring_stiffness>0</spring_stiffness>
        </dynamics>
      </axis>
    </joint>
    <link name='polysat/thruster_8'>
      <pose relative_to='polysat/thruster_8_joint'>0 0 0 0 -0 0</pose>
      <inertial>
        <pose>0 0 0 0 -0 0</pose>
        <mass>0.0001</mass>
        <inertia>
          <ixx>1.66667e-11</ixx>
          <ixy>0</ixy>
          <ixz>0</ixz>
          <iyy>1.66667e-11</iyy>
          <iyz>0</iyz>
          <izz>1.66667e-11</izz>
        </inertia>
      </inertial>
      <collision name='polysat/thruster_8_collision'>
        <pose>0 0 0 0 -0 0</pose>
        <geometry>
          <cylinder>
            <length>1e-07</length>
            <radius>1e-07</radius>
          </cylinder>
        </geometry>
        <surface>
          <contact>
            <ode/>
          </contact>
          <friction>
            <ode/>
          </friction>
        </surface>
      </collision>
      <visual name='polysat/thruster_8_visual'>
        <pose>0 0 0 0 -0 0</pose>
        <geometry>
          <cylinder>
            <length>1e-06</length>
            <radius>1e-07</radius>
          </cylinder>
        </geometry>
      </visual>
      <self_collide>0</self_collide>
    </link>
    <joint name='polysat/thruster_9_joint' type='revolute'>
      <pose relative_to='polysat/base_link'>0.5 -0.5 0 0 -0 0</pose>
      <parent>polysat/base_link</parent>
      <child>polysat/thruster_9</child>
      <axis>
        <xyz>1 0 0</xyz>
        <limit>
          <effort>0</effort>
          <velocity>0</velocity>
          <lower>-1e+16</lower>
          <upper>1e+16</upper>
        </limit>
        <dynamics>
          <spring_reference>0</spring_reference>
          <spring_stiffness>0</spring_stiffness>
        </dynamics>
      </axis>
    </joint>
    <link name='polysat/thruster_9'>
      <pose relative_to='polysat/thruster_9_joint'>0 0 0 0 -0 0</pose>
      <inertial>
        <pose>0 0 0 0 -0 0</pose>
        <mass>0.0001</mass>
        <inertia>
          <ixx>1.66667e-11</ixx>
          <ixy>0</ixy>
          <ixz>0</ixz>
          <iyy>1.66667e-11</iyy>
          <iyz>0</iyz>
          <izz>1.66667e-11</izz>
        </inertia>
      </inertial>
      <collision name='polysat/thruster_9_collision'>
        <pose>0 0 0 0 -0 0</pose>
        <geometry>
          <cylinder>
            <length>1e-07</length>
            <radius>1e-07</radius>
          </cylinder>
        </geometry>
        <surface>
          <contact>
            <ode/>
          </contact>
          <friction>
            <ode/>
          </friction>
        </surface>
      </collision>
      <visual name='polysat/thruster_9_visual'>
        <pose>0 0 0 0 -0 0</pose>
        <geometry>
          <cylinder>
            <length>1e-06</length>
            <radius>1e-07</radius>
          </cylinder>
        </geometry>
      </visual>
      <self_collide>0</self_collide>
    </link>
    <plugin name='gazebo_ros_control' filename='libgazebo_ros_control.so'>
      <robotNamespace>polysat</robotNamespace>
      <robotParam>polysat</robotParam>
    </plugin>
    <plugin name='polysat_0_thruster_model' filename='libsc_gazebo_thrust_plugin.so'>
      <thruster>
        <linkName>polysat/thruster_0</linkName>
        <jointName>polysat/thruster_0_joint</jointName>
        <cmdTopic>polysat/thrusters/thruster_0</cmdTopic>
        <angleTopic>polysat/thrusters/thruster_0_angle</angleTopic>
        <enableAngle>0</enableAngle>
      </thruster>
    </plugin>
    <plugin name='polysat_1_thruster_model' filename='libsc_gazebo_thrust_plugin.so'>
      <thruster>
        <linkName>polysat/thruster_1</linkName>
        <jointName>polysat/thruster_1_joint</jointName>
        <cmdTopic>polysat/thrusters/thruster_1</cmdTopic>
        <angleTopic>polysat/thrusters/thruster_1_angle</angleTopic>
        <enableAngle>0</enableAngle>
      </thruster>
    </plugin>
    <plugin name='polysat_2_thruster_model' filename='libsc_gazebo_thrust_plugin.so'>
      <thruster>
        <linkName>polysat/thruster_2</linkName>
        <jointName>polysat/thruster_2_joint</jointName>
        <cmdTopic>polysat/thrusters/thruster_2</cmdTopic>
        <angleTopic>polysat/thrusters/thruster_2_angle</angleTopic>
        <enableAngle>0</enableAngle>
      </thruster>
    </plugin>
    <plugin name='polysat_3_thruster_model' filename='libsc_gazebo_thrust_plugin.so'>
      <thruster>
        <linkName>polysat/thruster_3</linkName>
        <jointName>polysat/thruster_3_joint</jointName>
        <cmdTopic>polysat/thrusters/thruster_3</cmdTopic>
        <angleTopic>polysat/thrusters/thruster_3_angle</angleTopic>
        <enableAngle>0</enableAngle>
      </thruster>
    </plugin>
    <plugin name='polysat_4_thruster_model' filename='libsc_gazebo_thrust_plugin.so'>
      <thruster>
        <linkName>polysat/thruster_4</linkName>
        <jointName>polysat/thruster_4_joint</jointName>
        <cmdTopic>polysat/thrusters/thruster_4</cmdTopic>
        <angleTopic>polysat/thrusters/thruster_4_angle</angleTopic>
        <enableAngle>0</enableAngle>
      </thruster>
    </plugin>
    <plugin name='polysat_5_thruster_model' filename='libsc_gazebo_thrust_plugin.so'>
      <thruster>
        <linkName>polysat/thruster_5</linkName>
        <jointName>polysat/thruster_5_joint</jointName>
        <cmdTopic>polysat/thrusters/thruster_5</cmdTopic>
        <angleTopic>polysat/thrusters/thruster_5_angle</angleTopic>
        <enableAngle>0</enableAngle>
      </thruster>
    </plugin>
    <plugin name='polysat_6_thruster_model' filename='libsc_gazebo_thrust_plugin.so'>
      <thruster>
        <linkName>polysat/thruster_6</linkName>
        <jointName>polysat/thruster_6_joint</jointName>
        <cmdTopic>polysat/thrusters/thruster_6</cmdTopic>
        <angleTopic>polysat/thrusters/thruster_6_angle</angleTopic>
        <enableAngle>0</enableAngle>
      </thruster>
    </plugin>
    <plugin name='polysat_7_thruster_model' filename='libsc_gazebo_thrust_plugin.so'>
      <thruster>
        <linkName>polysat/thruster_7</linkName>
        <jointName>polysat/thruster_7_joint</jointName>
        <cmdTopic>polysat/thrusters/thruster_7</cmdTopic>
        <angleTopic>polysat/thrusters/thruster_7_angle</angleTopic>
        <enableAngle>0</enableAngle>
      </thruster>
    </plugin>
    <plugin name='polysat_8_thruster_model' filename='libsc_gazebo_thrust_plugin.so'>
      <thruster>
        <linkName>polysat/thruster_8</linkName>
        <jointName>polysat/thruster_8_joint</jointName>
        <cmdTopic>polysat/thrusters/thruster_8</cmdTopic>
        <angleTopic>polysat/thrusters/thruster_8_angle</angleTopic>
        <enableAngle>0</enableAngle>
      </thruster>
    </plugin>
    <plugin name='polysat_9_thruster_model' filename='libsc_gazebo_thrust_plugin.so'>
      <thruster>
        <linkName>polysat/thruster_9</linkName>
        <jointName>polysat/thruster_9_joint</jointName>
        <cmdTopic>polysat/thrusters/thruster_9</cmdTopic>
        <angleTopic>polysat/thrusters/thruster_9_angle</angleTopic>
        <enableAngle>0</enableAngle>
      </thruster>
    </plugin>
    <plugin name='polysat_10_thruster_model' filename='libsc_gazebo_thrust_plugin.so'>
      <thruster>
        <linkName>polysat/thruster_10</linkName>
        <jointName>polysat/thruster_10_joint</jointName>
        <cmdTopic>polysat/thrusters/thruster_10</cmdTopic>
        <angleTopic>polysat/thrusters/thruster_10_angle</angleTopic>
        <enableAngle>0</enableAngle>
      </thruster>
    </plugin>
    <plugin name='polysat_11_thruster_model' filename='libsc_gazebo_thrust_plugin.so'>
      <thruster>
        <linkName>polysat/thruster_11</linkName>
        <jointName>polysat/thruster_11_joint</jointName>
        <cmdTopic>polysat/thrusters/thruster_11</cmdTopic>
        <angleTopic>polysat/thrusters/thruster_11_angle</angleTopic>
        <enableAngle>0</enableAngle>
      </thruster>
    </plugin>
    <plugin name='polysat_12_thruster_model' filename='libsc_gazebo_thrust_plugin.so'>
      <thruster>
        <linkName>polysat/thruster_12</linkName>
        <jointName>polysat/thruster_12_joint</jointName>
        <cmdTopic>polysat/thrusters/thruster_12</cmdTopic>
        <angleTopic>polysat/thrusters/thruster_12_angle</angleTopic>
        <enableAngle>0</enableAngle>
      </thruster>
    </plugin>
    <plugin name='polysat_13_thruster_model' filename='libsc_gazebo_thrust_plugin.so'>
      <thruster>
        <linkName>polysat/thruster_13</linkName>
        <jointName>polysat/thruster_13_joint</jointName>
        <cmdTopic>polysat/thrusters/thruster_13</cmdTopic>
        <angleTopic>polysat/thrusters/thruster_13_angle</angleTopic>
        <enableAngle>0</enableAngle>
      </thruster>
    </plugin>
    <plugin name='libsc_imu_gazebo_plugin' filename='libsc_imu_gazebo_plugin.so'>
      <robot_namespace>polysat</robot_namespace>
      <link_name>polysat/imu_link</link_name>
      <sensor_topic>imu</sensor_topic>
      <gyroscope_noise_density>0.0003394</gyroscope_noise_density>
      <gyroscope_random_walk>3.8785e-05</gyroscope_random_walk>
      <gyroscope_bias_correlation_time>1000.0</gyroscope_bias_correlation_time>
      <gyroscope_turn_on_bias_sigma>0.0087</gyroscope_turn_on_bias_sigma>
      <accelerometer_noise_density>0.004</accelerometer_noise_density>
      <accelerometer_random_walk>0.006</accelerometer_random_walk>
      <accelerometer_bias_correlation_time>300.0</accelerometer_bias_correlation_time>
      <accelerometer_turn_on_bias_sigma>0.196</accelerometer_turn_on_bias_sigma>
      <orientation_noise>0.01</orientation_noise>
      <update_rate>50</update_rate>
      <enable_gazebo_messages>0</enable_gazebo_messages>
      <enable_local_ned_frame>0</enable_local_ned_frame>
      <static_reference_frame>world</static_reference_frame>
    </plugin>
    <static>0</static>
    <plugin name='pose_3d_plugin' filename='libsc_pose_gt_plugin.so'>
      <robot_namespace>polysat</robot_namespace>
      <link_name>polysat/base_link</link_name>
      <sensor_topic>pose_gt</sensor_topic>
      <static_reference_frame>world</static_reference_frame>
      <noise_sigma>0.0</noise_sigma>
      <noise_amplitude>0.0</noise_amplitude>
      <update_rate>20</update_rate>
      <enable_gazebo_messages>0</enable_gazebo_messages>
      <publish_ned_odom>0</publish_ned_odom>
    </plugin>
  </model>
</sdf>
