<?xml version="1.0" ?>
<!-- =================================================================================== -->
<!-- |    This document was autogenerated by xacro from polysat_robot.urdf.xacro       | -->
<!-- |    EDITING THIS FILE BY HAND IS NOT RECOMMENDED                                 | -->
<!-- =================================================================================== -->
<robot name="polysat">
  <!-- "Dummy base link to eliminate root link inertia warning -->
  <link name="polysat/base_link"/>
  <!-- Start of main robot body -->
  <link name="polysat/polysat_link">
    <inertial>
      <origin rpy="0 0 0" xyz="0 0 0"/>
      <mass value="50.0"/>
      <inertia ixx="10.0" ixy="0.0" ixz="0.0" iyy="10.0" iyz="0.0" izz="10.0"/>
    </inertial>
    <visual>
      <origin rpy="1.570796326794 0 0" xyz="-0.5 1.0 -0.5"/>
      <geometry>
        <mesh filename="file:///home/carson/spaceship_ws/src/spacecraft_sim/urdf/robots/polysat_description/meshes/base.stl" scale="0.001 0.001 0.001"/>
      </geometry>
    </visual>
    <collision>
      <origin rpy="1.570796326794 0 0" xyz="-0.5 1.0 -0.5"/>
      <geometry>
        <mesh filename="file:///home/carson/spaceship_ws/src/spacecraft_sim/urdf/robots/polysat_description/meshes/base.stl" scale="0.001 0.001 0.001"/>
      </geometry>
    </collision>
  </link>
  <link name="polysat/thruster_0_visual">
    <inertial>
      <mass value="0.0001"/>
      <origin rpy="0 0 0" xyz="0 0 0"/>
      <inertia ixx="1.666666e-11" ixy="0.0" ixz="0.0" iyy="1.666666e-11" iyz="0.0" izz="1.666666e-11"/>
    </inertial>
    <visual>
      <origin rpy="0 0 0" xyz="0 0 0"/>
      <geometry>
        <mesh filename="file:///home/carson/spaceship_ws/src/spacecraft_sim/urdf/robots/polysat_description/meshes/thruster.stl" scale="0.001 0.001 0.001"/>
      </geometry>
    </visual>
    <collision>
      <origin rpy="0 0 0" xyz="0 0 0"/>
      <geometry>
        <mesh filename="file:///home/carson/spaceship_ws/src/spacecraft_sim/urdf/robots/polysat_description/meshes/thruster.stl" scale="0.001 0.001 0.001"/>
      </geometry>
    </collision>
  </link>
  <joint name="polysat/thruster_0_visual_joint" type="fixed">
    <origin rpy="0 0 0" xyz="0.355 -0.075 0.5"/>
    <parent link="polysat/base_link"/>
    <child link="polysat/thruster_0_visual"/>
  </joint>
  <link name="polysat/thrust_plume_0_visual">
    <inertial>
      <mass value="0.0001"/>
      <origin rpy="0 0 0" xyz="0 0 0"/>
      <inertia ixx="1.666666e-11" ixy="0.0" ixz="0.0" iyy="1.666666e-11" iyz="0.0" izz="1.666666e-11"/>
    </inertial>
    <visual>
      <origin rpy="0 0 0" xyz="0 0 0"/>
      <geometry>
        <mesh filename="file:///home/carson/spaceship_ws/src/spacecraft_sim/urdf/robots/polysat_description/meshes/thrust_plume.stl" scale="0.001 0.001 0.001"/>
      </geometry>
    </visual>
    <collision>
      <origin rpy="0 0 0" xyz="0 0 0"/>
      <geometry>
        <mesh filename="file:///home/carson/spaceship_ws/src/spacecraft_sim/urdf/robots/polysat_description/meshes/thrust_plume.stl" scale="0.001 0.001 0.001"/>
      </geometry>
    </collision>
  </link>
  <joint name="polysat/thrust_plume_0_visual_joint" type="fixed">
    <origin rpy="1.5707963267948966 0 0" xyz="0.265 0.165 0.55"/>
    <parent link="polysat/base_link"/>
    <child link="polysat/thrust_plume_0_visual"/>
  </joint>
  <!-- Connect dummy link to main link -->
  <joint name="polysat/polysat_base_joint" type="fixed">
    <origin rpy="0 0 0" xyz="0 0 0"/>
    <parent link="polysat/base_link"/>
    <child link="polysat/polysat_link"/>
  </joint>
  <gazebo>
    <plugin filename="libgazebo_ros_control.so" name="gazebo_ros_control">
      <robotNamespace>polysat</robotNamespace>
      <robotParam>polysat</robotParam>
    </plugin>
  </gazebo>
  <link name="polysat/thruster_0">
    <inertial>
      <mass value="0.0001"/>
      <origin rpy="0 0 0" xyz="0 0 0"/>
      <inertia ixx="1.666666e-11" ixy="0.0" ixz="0.0" iyy="1.666666e-11" iyz="0.0" izz="1.666666e-11"/>
    </inertial>
    <visual>
      <geometry>
        <cylinder length="0.000001" radius="0.0000001"/>
      </geometry>
      <origin rpy="0 0 0" xyz="0 0 0"/>
    </visual>
    <collision>
      <geometry>
        <cylinder length="0.0000001" radius="0.0000001"/>
      </geometry>
      <origin rpy="0 0 0" xyz="0 0 0"/>
    </collision>
  </link>
  <joint name="polysat/thruster_0_joint" type="continuous">
    <origin rpy="0 0 0" xyz="0.5 0 0.5"/>
    <parent link="polysat/base_link"/>
    <child link="polysat/thruster_0"/>
    <axis xyz="1 0 0"/>
    <limit effort="0" lower="0" upper="0" velocity="0"/>
  </joint>
  <gazebo>
    <plugin filename="libsc_gazebo_thrust_plugin.so" name="polysat_0_thruster_model">
      <thruster>
        <linkName>polysat/thruster_0</linkName>
        <jointName>polysat/thruster_0_joint</jointName>
        <cmdTopic>polysat/thrusters/thruster_0</cmdTopic>
        <angleTopic>polysat/thrusters/thruster_0_angle</angleTopic>
        <enableAngle>false</enableAngle>
      </thruster>
    </plugin>
  </gazebo>
  <!-- <gazebo>
      <plugin name="${namespace}_${thruster_id}_thruster_model" filename="libLedPlugin.so">
        <light>
          <id>${namespace}/thruster_${thruster_id}/light</id>
          <block>
            <duration>1</duration>
            <interval>1</interval>
            <color>1 0.5 0.5</color>
          </block>
          <enable>true</enable>
        </light>
      </plugin>
    </gazebo> -->
  <!--gazebo reference="${namespace}/thruster_${thruster_id}">
      <xacro:led_stripe name="light_${thruster_id}" range="30" linear="0.2" constant="0.1" quadratic="0.0025"
        inner_angle="2.8" outer_angle="2.9" 
        pose="0 0 0 0 0 0"/>
    </gazebo-->
  <gazebo reference="polysat/thruster_0">
    <selfCollide>false</selfCollide>
  </gazebo>
  <link name="polysat/thruster_1">
    <inertial>
      <mass value="0.0001"/>
      <origin rpy="0 0 0" xyz="0 0 0"/>
      <inertia ixx="1.666666e-11" ixy="0.0" ixz="0.0" iyy="1.666666e-11" iyz="0.0" izz="1.666666e-11"/>
    </inertial>
    <visual>
      <geometry>
        <cylinder length="0.000001" radius="0.0000001"/>
      </geometry>
      <origin rpy="0 0 0" xyz="0 0 0"/>
    </visual>
    <collision>
      <geometry>
        <cylinder length="0.0000001" radius="0.0000001"/>
      </geometry>
      <origin rpy="0 0 0" xyz="0 0 0"/>
    </collision>
  </link>
  <joint name="polysat/thruster_1_joint" type="continuous">
    <origin rpy="0 0 0" xyz="0.5 0 -0.5"/>
    <parent link="polysat/base_link"/>
    <child link="polysat/thruster_1"/>
    <axis xyz="1 0 0"/>
    <limit effort="0" lower="0" upper="0" velocity="0"/>
  </joint>
  <gazebo>
    <plugin filename="libsc_gazebo_thrust_plugin.so" name="polysat_1_thruster_model">
      <thruster>
        <linkName>polysat/thruster_1</linkName>
        <jointName>polysat/thruster_1_joint</jointName>
        <cmdTopic>polysat/thrusters/thruster_1</cmdTopic>
        <angleTopic>polysat/thrusters/thruster_1_angle</angleTopic>
        <enableAngle>false</enableAngle>
      </thruster>
    </plugin>
  </gazebo>
  <!-- <gazebo>
      <plugin name="${namespace}_${thruster_id}_thruster_model" filename="libLedPlugin.so">
        <light>
          <id>${namespace}/thruster_${thruster_id}/light</id>
          <block>
            <duration>1</duration>
            <interval>1</interval>
            <color>1 0.5 0.5</color>
          </block>
          <enable>true</enable>
        </light>
      </plugin>
    </gazebo> -->
  <!--gazebo reference="${namespace}/thruster_${thruster_id}">
      <xacro:led_stripe name="light_${thruster_id}" range="30" linear="0.2" constant="0.1" quadratic="0.0025"
        inner_angle="2.8" outer_angle="2.9" 
        pose="0 0 0 0 0 0"/>
    </gazebo-->
  <gazebo reference="polysat/thruster_1">
    <selfCollide>false</selfCollide>
  </gazebo>
  <link name="polysat/thruster_2">
    <inertial>
      <mass value="0.0001"/>
      <origin rpy="0 0 0" xyz="0 0 0"/>
      <inertia ixx="1.666666e-11" ixy="0.0" ixz="0.0" iyy="1.666666e-11" iyz="0.0" izz="1.666666e-11"/>
    </inertial>
    <visual>
      <geometry>
        <cylinder length="0.000001" radius="0.0000001"/>
      </geometry>
      <origin rpy="0 0 0" xyz="0 0 0"/>
    </visual>
    <collision>
      <geometry>
        <cylinder length="0.0000001" radius="0.0000001"/>
      </geometry>
      <origin rpy="0 0 0" xyz="0 0 0"/>
    </collision>
  </link>
  <joint name="polysat/thruster_2_joint" type="continuous">
    <origin rpy="0 0 3.1415926535" xyz="-0.5 0 0.5"/>
    <parent link="polysat/base_link"/>
    <child link="polysat/thruster_2"/>
    <axis xyz="1 0 0"/>
    <limit effort="0" lower="0" upper="0" velocity="0"/>
  </joint>
  <gazebo>
    <plugin filename="libsc_gazebo_thrust_plugin.so" name="polysat_2_thruster_model">
      <thruster>
        <linkName>polysat/thruster_2</linkName>
        <jointName>polysat/thruster_2_joint</jointName>
        <cmdTopic>polysat/thrusters/thruster_2</cmdTopic>
        <angleTopic>polysat/thrusters/thruster_2_angle</angleTopic>
        <enableAngle>false</enableAngle>
      </thruster>
    </plugin>
  </gazebo>
  <!-- <gazebo>
      <plugin name="${namespace}_${thruster_id}_thruster_model" filename="libLedPlugin.so">
        <light>
          <id>${namespace}/thruster_${thruster_id}/light</id>
          <block>
            <duration>1</duration>
            <interval>1</interval>
            <color>1 0.5 0.5</color>
          </block>
          <enable>true</enable>
        </light>
      </plugin>
    </gazebo> -->
  <!--gazebo reference="${namespace}/thruster_${thruster_id}">
      <xacro:led_stripe name="light_${thruster_id}" range="30" linear="0.2" constant="0.1" quadratic="0.0025"
        inner_angle="2.8" outer_angle="2.9" 
        pose="0 0 0 0 0 0"/>
    </gazebo-->
  <gazebo reference="polysat/thruster_2">
    <selfCollide>false</selfCollide>
  </gazebo>
  <link name="polysat/thruster_3">
    <inertial>
      <mass value="0.0001"/>
      <origin rpy="0 0 0" xyz="0 0 0"/>
      <inertia ixx="1.666666e-11" ixy="0.0" ixz="0.0" iyy="1.666666e-11" iyz="0.0" izz="1.666666e-11"/>
    </inertial>
    <visual>
      <geometry>
        <cylinder length="0.000001" radius="0.0000001"/>
      </geometry>
      <origin rpy="0 0 0" xyz="0 0 0"/>
    </visual>
    <collision>
      <geometry>
        <cylinder length="0.0000001" radius="0.0000001"/>
      </geometry>
      <origin rpy="0 0 0" xyz="0 0 0"/>
    </collision>
  </link>
  <joint name="polysat/thruster_3_joint" type="continuous">
    <origin rpy="0 0 3.1415926535" xyz="-0.5 0 -0.5"/>
    <parent link="polysat/base_link"/>
    <child link="polysat/thruster_3"/>
    <axis xyz="1 0 0"/>
    <limit effort="0" lower="0" upper="0" velocity="0"/>
  </joint>
  <gazebo>
    <plugin filename="libsc_gazebo_thrust_plugin.so" name="polysat_3_thruster_model">
      <thruster>
        <linkName>polysat/thruster_3</linkName>
        <jointName>polysat/thruster_3_joint</jointName>
        <cmdTopic>polysat/thrusters/thruster_3</cmdTopic>
        <angleTopic>polysat/thrusters/thruster_3_angle</angleTopic>
        <enableAngle>false</enableAngle>
      </thruster>
    </plugin>
  </gazebo>
  <!-- <gazebo>
      <plugin name="${namespace}_${thruster_id}_thruster_model" filename="libLedPlugin.so">
        <light>
          <id>${namespace}/thruster_${thruster_id}/light</id>
          <block>
            <duration>1</duration>
            <interval>1</interval>
            <color>1 0.5 0.5</color>
          </block>
          <enable>true</enable>
        </light>
      </plugin>
    </gazebo> -->
  <!--gazebo reference="${namespace}/thruster_${thruster_id}">
      <xacro:led_stripe name="light_${thruster_id}" range="30" linear="0.2" constant="0.1" quadratic="0.0025"
        inner_angle="2.8" outer_angle="2.9" 
        pose="0 0 0 0 0 0"/>
    </gazebo-->
  <gazebo reference="polysat/thruster_3">
    <selfCollide>false</selfCollide>
  </gazebo>
  <link name="polysat/thruster_4">
    <inertial>
      <mass value="0.0001"/>
      <origin rpy="0 0 0" xyz="0 0 0"/>
      <inertia ixx="1.666666e-11" ixy="0.0" ixz="0.0" iyy="1.666666e-11" iyz="0.0" izz="1.666666e-11"/>
    </inertial>
    <visual>
      <geometry>
        <cylinder length="0.000001" radius="0.0000001"/>
      </geometry>
      <origin rpy="0 0 0" xyz="0 0 0"/>
    </visual>
    <collision>
      <geometry>
        <cylinder length="0.0000001" radius="0.0000001"/>
      </geometry>
      <origin rpy="0 0 0" xyz="0 0 0"/>
    </collision>
  </link>
  <joint name="polysat/thruster_4_joint" type="continuous">
    <origin rpy="0 -1.5707963268 0" xyz="0 0.5 0.5"/>
    <parent link="polysat/base_link"/>
    <child link="polysat/thruster_4"/>
    <axis xyz="1 0 0"/>
    <limit effort="0" lower="0" upper="0" velocity="0"/>
  </joint>
  <gazebo>
    <plugin filename="libsc_gazebo_thrust_plugin.so" name="polysat_4_thruster_model">
      <thruster>
        <linkName>polysat/thruster_4</linkName>
        <jointName>polysat/thruster_4_joint</jointName>
        <cmdTopic>polysat/thrusters/thruster_4</cmdTopic>
        <angleTopic>polysat/thrusters/thruster_4_angle</angleTopic>
        <enableAngle>false</enableAngle>
      </thruster>
    </plugin>
  </gazebo>
  <!-- <gazebo>
      <plugin name="${namespace}_${thruster_id}_thruster_model" filename="libLedPlugin.so">
        <light>
          <id>${namespace}/thruster_${thruster_id}/light</id>
          <block>
            <duration>1</duration>
            <interval>1</interval>
            <color>1 0.5 0.5</color>
          </block>
          <enable>true</enable>
        </light>
      </plugin>
    </gazebo> -->
  <!--gazebo reference="${namespace}/thruster_${thruster_id}">
      <xacro:led_stripe name="light_${thruster_id}" range="30" linear="0.2" constant="0.1" quadratic="0.0025"
        inner_angle="2.8" outer_angle="2.9" 
        pose="0 0 0 0 0 0"/>
    </gazebo-->
  <gazebo reference="polysat/thruster_4">
    <selfCollide>false</selfCollide>
  </gazebo>
  <link name="polysat/thruster_5">
    <inertial>
      <mass value="0.0001"/>
      <origin rpy="0 0 0" xyz="0 0 0"/>
      <inertia ixx="1.666666e-11" ixy="0.0" ixz="0.0" iyy="1.666666e-11" iyz="0.0" izz="1.666666e-11"/>
    </inertial>
    <visual>
      <geometry>
        <cylinder length="0.000001" radius="0.0000001"/>
      </geometry>
      <origin rpy="0 0 0" xyz="0 0 0"/>
    </visual>
    <collision>
      <geometry>
        <cylinder length="0.0000001" radius="0.0000001"/>
      </geometry>
      <origin rpy="0 0 0" xyz="0 0 0"/>
    </collision>
  </link>
  <joint name="polysat/thruster_5_joint" type="continuous">
    <origin rpy="0 -1.5707963268 0" xyz="0 -0.5 0.5"/>
    <parent link="polysat/base_link"/>
    <child link="polysat/thruster_5"/>
    <axis xyz="1 0 0"/>
    <limit effort="0" lower="0" upper="0" velocity="0"/>
  </joint>
  <gazebo>
    <plugin filename="libsc_gazebo_thrust_plugin.so" name="polysat_5_thruster_model">
      <thruster>
        <linkName>polysat/thruster_5</linkName>
        <jointName>polysat/thruster_5_joint</jointName>
        <cmdTopic>polysat/thrusters/thruster_5</cmdTopic>
        <angleTopic>polysat/thrusters/thruster_5_angle</angleTopic>
        <enableAngle>false</enableAngle>
      </thruster>
    </plugin>
  </gazebo>
  <!-- <gazebo>
      <plugin name="${namespace}_${thruster_id}_thruster_model" filename="libLedPlugin.so">
        <light>
          <id>${namespace}/thruster_${thruster_id}/light</id>
          <block>
            <duration>1</duration>
            <interval>1</interval>
            <color>1 0.5 0.5</color>
          </block>
          <enable>true</enable>
        </light>
      </plugin>
    </gazebo> -->
  <!--gazebo reference="${namespace}/thruster_${thruster_id}">
      <xacro:led_stripe name="light_${thruster_id}" range="30" linear="0.2" constant="0.1" quadratic="0.0025"
        inner_angle="2.8" outer_angle="2.9" 
        pose="0 0 0 0 0 0"/>
    </gazebo-->
  <gazebo reference="polysat/thruster_5">
    <selfCollide>false</selfCollide>
  </gazebo>
  <link name="polysat/thruster_6">
    <inertial>
      <mass value="0.0001"/>
      <origin rpy="0 0 0" xyz="0 0 0"/>
      <inertia ixx="1.666666e-11" ixy="0.0" ixz="0.0" iyy="1.666666e-11" iyz="0.0" izz="1.666666e-11"/>
    </inertial>
    <visual>
      <geometry>
        <cylinder length="0.000001" radius="0.0000001"/>
      </geometry>
      <origin rpy="0 0 0" xyz="0 0 0"/>
    </visual>
    <collision>
      <geometry>
        <cylinder length="0.0000001" radius="0.0000001"/>
      </geometry>
      <origin rpy="0 0 0" xyz="0 0 0"/>
    </collision>
  </link>
  <joint name="polysat/thruster_6_joint" type="continuous">
    <origin rpy="0 1.5707963268 0" xyz="0 0.5 -0.5"/>
    <parent link="polysat/base_link"/>
    <child link="polysat/thruster_6"/>
    <axis xyz="1 0 0"/>
    <limit effort="0" lower="0" upper="0" velocity="0"/>
  </joint>
  <gazebo>
    <plugin filename="libsc_gazebo_thrust_plugin.so" name="polysat_6_thruster_model">
      <thruster>
        <linkName>polysat/thruster_6</linkName>
        <jointName>polysat/thruster_6_joint</jointName>
        <cmdTopic>polysat/thrusters/thruster_6</cmdTopic>
        <angleTopic>polysat/thrusters/thruster_6_angle</angleTopic>
        <enableAngle>false</enableAngle>
      </thruster>
    </plugin>
  </gazebo>
  <!-- <gazebo>
      <plugin name="${namespace}_${thruster_id}_thruster_model" filename="libLedPlugin.so">
        <light>
          <id>${namespace}/thruster_${thruster_id}/light</id>
          <block>
            <duration>1</duration>
            <interval>1</interval>
            <color>1 0.5 0.5</color>
          </block>
          <enable>true</enable>
        </light>
      </plugin>
    </gazebo> -->
  <!--gazebo reference="${namespace}/thruster_${thruster_id}">
      <xacro:led_stripe name="light_${thruster_id}" range="30" linear="0.2" constant="0.1" quadratic="0.0025"
        inner_angle="2.8" outer_angle="2.9" 
        pose="0 0 0 0 0 0"/>
    </gazebo-->
  <gazebo reference="polysat/thruster_6">
    <selfCollide>false</selfCollide>
  </gazebo>
  <link name="polysat/thruster_7">
    <inertial>
      <mass value="0.0001"/>
      <origin rpy="0 0 0" xyz="0 0 0"/>
      <inertia ixx="1.666666e-11" ixy="0.0" ixz="0.0" iyy="1.666666e-11" iyz="0.0" izz="1.666666e-11"/>
    </inertial>
    <visual>
      <geometry>
        <cylinder length="0.000001" radius="0.0000001"/>
      </geometry>
      <origin rpy="0 0 0" xyz="0 0 0"/>
    </visual>
    <collision>
      <geometry>
        <cylinder length="0.0000001" radius="0.0000001"/>
      </geometry>
      <origin rpy="0 0 0" xyz="0 0 0"/>
    </collision>
  </link>
  <joint name="polysat/thruster_7_joint" type="continuous">
    <origin rpy="0 1.5707963268 0" xyz="0 -0.5 -0.5"/>
    <parent link="polysat/base_link"/>
    <child link="polysat/thruster_7"/>
    <axis xyz="1 0 0"/>
    <limit effort="0" lower="0" upper="0" velocity="0"/>
  </joint>
  <gazebo>
    <plugin filename="libsc_gazebo_thrust_plugin.so" name="polysat_7_thruster_model">
      <thruster>
        <linkName>polysat/thruster_7</linkName>
        <jointName>polysat/thruster_7_joint</jointName>
        <cmdTopic>polysat/thrusters/thruster_7</cmdTopic>
        <angleTopic>polysat/thrusters/thruster_7_angle</angleTopic>
        <enableAngle>false</enableAngle>
      </thruster>
    </plugin>
  </gazebo>
  <!-- <gazebo>
      <plugin name="${namespace}_${thruster_id}_thruster_model" filename="libLedPlugin.so">
        <light>
          <id>${namespace}/thruster_${thruster_id}/light</id>
          <block>
            <duration>1</duration>
            <interval>1</interval>
            <color>1 0.5 0.5</color>
          </block>
          <enable>true</enable>
        </light>
      </plugin>
    </gazebo> -->
  <!--gazebo reference="${namespace}/thruster_${thruster_id}">
      <xacro:led_stripe name="light_${thruster_id}" range="30" linear="0.2" constant="0.1" quadratic="0.0025"
        inner_angle="2.8" outer_angle="2.9" 
        pose="0 0 0 0 0 0"/>
    </gazebo-->
  <gazebo reference="polysat/thruster_7">
    <selfCollide>false</selfCollide>
  </gazebo>
  <link name="polysat/thruster_8">
    <inertial>
      <mass value="0.0001"/>
      <origin rpy="0 0 0" xyz="0 0 0"/>
      <inertia ixx="1.666666e-11" ixy="0.0" ixz="0.0" iyy="1.666666e-11" iyz="0.0" izz="1.666666e-11"/>
    </inertial>
    <visual>
      <geometry>
        <cylinder length="0.000001" radius="0.0000001"/>
      </geometry>
      <origin rpy="0 0 0" xyz="0 0 0"/>
    </visual>
    <collision>
      <geometry>
        <cylinder length="0.0000001" radius="0.0000001"/>
      </geometry>
      <origin rpy="0 0 0" xyz="0 0 0"/>
    </collision>
  </link>
  <joint name="polysat/thruster_8_joint" type="continuous">
    <origin rpy="0 0 0" xyz="0.5 0.5 0"/>
    <parent link="polysat/base_link"/>
    <child link="polysat/thruster_8"/>
    <axis xyz="1 0 0"/>
    <limit effort="0" lower="0" upper="0" velocity="0"/>
  </joint>
  <gazebo>
    <plugin filename="libsc_gazebo_thrust_plugin.so" name="polysat_8_thruster_model">
      <thruster>
        <linkName>polysat/thruster_8</linkName>
        <jointName>polysat/thruster_8_joint</jointName>
        <cmdTopic>polysat/thrusters/thruster_8</cmdTopic>
        <angleTopic>polysat/thrusters/thruster_8_angle</angleTopic>
        <enableAngle>false</enableAngle>
      </thruster>
    </plugin>
  </gazebo>
  <!-- <gazebo>
      <plugin name="${namespace}_${thruster_id}_thruster_model" filename="libLedPlugin.so">
        <light>
          <id>${namespace}/thruster_${thruster_id}/light</id>
          <block>
            <duration>1</duration>
            <interval>1</interval>
            <color>1 0.5 0.5</color>
          </block>
          <enable>true</enable>
        </light>
      </plugin>
    </gazebo> -->
  <!--gazebo reference="${namespace}/thruster_${thruster_id}">
      <xacro:led_stripe name="light_${thruster_id}" range="30" linear="0.2" constant="0.1" quadratic="0.0025"
        inner_angle="2.8" outer_angle="2.9" 
        pose="0 0 0 0 0 0"/>
    </gazebo-->
  <gazebo reference="polysat/thruster_8">
    <selfCollide>false</selfCollide>
  </gazebo>
  <link name="polysat/thruster_9">
    <inertial>
      <mass value="0.0001"/>
      <origin rpy="0 0 0" xyz="0 0 0"/>
      <inertia ixx="1.666666e-11" ixy="0.0" ixz="0.0" iyy="1.666666e-11" iyz="0.0" izz="1.666666e-11"/>
    </inertial>
    <visual>
      <geometry>
        <cylinder length="0.000001" radius="0.0000001"/>
      </geometry>
      <origin rpy="0 0 0" xyz="0 0 0"/>
    </visual>
    <collision>
      <geometry>
        <cylinder length="0.0000001" radius="0.0000001"/>
      </geometry>
      <origin rpy="0 0 0" xyz="0 0 0"/>
    </collision>
  </link>
  <joint name="polysat/thruster_9_joint" type="continuous">
    <origin rpy="0 0 0" xyz="0.5 -0.5 0"/>
    <parent link="polysat/base_link"/>
    <child link="polysat/thruster_9"/>
    <axis xyz="1 0 0"/>
    <limit effort="0" lower="0" upper="0" velocity="0"/>
  </joint>
  <gazebo>
    <plugin filename="libsc_gazebo_thrust_plugin.so" name="polysat_9_thruster_model">
      <thruster>
        <linkName>polysat/thruster_9</linkName>
        <jointName>polysat/thruster_9_joint</jointName>
        <cmdTopic>polysat/thrusters/thruster_9</cmdTopic>
        <angleTopic>polysat/thrusters/thruster_9_angle</angleTopic>
        <enableAngle>false</enableAngle>
      </thruster>
    </plugin>
  </gazebo>
  <!-- <gazebo>
      <plugin name="${namespace}_${thruster_id}_thruster_model" filename="libLedPlugin.so">
        <light>
          <id>${namespace}/thruster_${thruster_id}/light</id>
          <block>
            <duration>1</duration>
            <interval>1</interval>
            <color>1 0.5 0.5</color>
          </block>
          <enable>true</enable>
        </light>
      </plugin>
    </gazebo> -->
  <!--gazebo reference="${namespace}/thruster_${thruster_id}">
      <xacro:led_stripe name="light_${thruster_id}" range="30" linear="0.2" constant="0.1" quadratic="0.0025"
        inner_angle="2.8" outer_angle="2.9" 
        pose="0 0 0 0 0 0"/>
    </gazebo-->
  <gazebo reference="polysat/thruster_9">
    <selfCollide>false</selfCollide>
  </gazebo>
  <link name="polysat/thruster_10">
    <inertial>
      <mass value="0.0001"/>
      <origin rpy="0 0 0" xyz="0 0 0"/>
      <inertia ixx="1.666666e-11" ixy="0.0" ixz="0.0" iyy="1.666666e-11" iyz="0.0" izz="1.666666e-11"/>
    </inertial>
    <visual>
      <geometry>
        <cylinder length="0.000001" radius="0.0000001"/>
      </geometry>
      <origin rpy="0 0 0" xyz="0 0 0"/>
    </visual>
    <collision>
      <geometry>
        <cylinder length="0.0000001" radius="0.0000001"/>
      </geometry>
      <origin rpy="0 0 0" xyz="0 0 0"/>
    </collision>
  </link>
  <joint name="polysat/thruster_10_joint" type="continuous">
    <origin rpy="0 0 3.1415926535" xyz="-0.5 0.5 0"/>
    <parent link="polysat/base_link"/>
    <child link="polysat/thruster_10"/>
    <axis xyz="1 0 0"/>
    <limit effort="0" lower="0" upper="0" velocity="0"/>
  </joint>
  <gazebo>
    <plugin filename="libsc_gazebo_thrust_plugin.so" name="polysat_10_thruster_model">
      <thruster>
        <linkName>polysat/thruster_10</linkName>
        <jointName>polysat/thruster_10_joint</jointName>
        <cmdTopic>polysat/thrusters/thruster_10</cmdTopic>
        <angleTopic>polysat/thrusters/thruster_10_angle</angleTopic>
        <enableAngle>false</enableAngle>
      </thruster>
    </plugin>
  </gazebo>
  <!-- <gazebo>
      <plugin name="${namespace}_${thruster_id}_thruster_model" filename="libLedPlugin.so">
        <light>
          <id>${namespace}/thruster_${thruster_id}/light</id>
          <block>
            <duration>1</duration>
            <interval>1</interval>
            <color>1 0.5 0.5</color>
          </block>
          <enable>true</enable>
        </light>
      </plugin>
    </gazebo> -->
  <!--gazebo reference="${namespace}/thruster_${thruster_id}">
      <xacro:led_stripe name="light_${thruster_id}" range="30" linear="0.2" constant="0.1" quadratic="0.0025"
        inner_angle="2.8" outer_angle="2.9" 
        pose="0 0 0 0 0 0"/>
    </gazebo-->
  <gazebo reference="polysat/thruster_10">
    <selfCollide>false</selfCollide>
  </gazebo>
  <link name="polysat/thruster_11">
    <inertial>
      <mass value="0.0001"/>
      <origin rpy="0 0 0" xyz="0 0 0"/>
      <inertia ixx="1.666666e-11" ixy="0.0" ixz="0.0" iyy="1.666666e-11" iyz="0.0" izz="1.666666e-11"/>
    </inertial>
    <visual>
      <geometry>
        <cylinder length="0.000001" radius="0.0000001"/>
      </geometry>
      <origin rpy="0 0 0" xyz="0 0 0"/>
    </visual>
    <collision>
      <geometry>
        <cylinder length="0.0000001" radius="0.0000001"/>
      </geometry>
      <origin rpy="0 0 0" xyz="0 0 0"/>
    </collision>
  </link>
  <joint name="polysat/thruster_11_joint" type="continuous">
    <origin rpy="0 0 3.1415926535" xyz="-0.5 -0.5 0"/>
    <parent link="polysat/base_link"/>
    <child link="polysat/thruster_11"/>
    <axis xyz="1 0 0"/>
    <limit effort="0" lower="0" upper="0" velocity="0"/>
  </joint>
  <gazebo>
    <plugin filename="libsc_gazebo_thrust_plugin.so" name="polysat_11_thruster_model">
      <thruster>
        <linkName>polysat/thruster_11</linkName>
        <jointName>polysat/thruster_11_joint</jointName>
        <cmdTopic>polysat/thrusters/thruster_11</cmdTopic>
        <angleTopic>polysat/thrusters/thruster_11_angle</angleTopic>
        <enableAngle>false</enableAngle>
      </thruster>
    </plugin>
  </gazebo>
  <!-- <gazebo>
      <plugin name="${namespace}_${thruster_id}_thruster_model" filename="libLedPlugin.so">
        <light>
          <id>${namespace}/thruster_${thruster_id}/light</id>
          <block>
            <duration>1</duration>
            <interval>1</interval>
            <color>1 0.5 0.5</color>
          </block>
          <enable>true</enable>
        </light>
      </plugin>
    </gazebo> -->
  <!--gazebo reference="${namespace}/thruster_${thruster_id}">
      <xacro:led_stripe name="light_${thruster_id}" range="30" linear="0.2" constant="0.1" quadratic="0.0025"
        inner_angle="2.8" outer_angle="2.9" 
        pose="0 0 0 0 0 0"/>
    </gazebo-->
  <gazebo reference="polysat/thruster_11">
    <selfCollide>false</selfCollide>
  </gazebo>
  <link name="polysat/thruster_12">
    <inertial>
      <mass value="0.0001"/>
      <origin rpy="0 0 0" xyz="0 0 0"/>
      <inertia ixx="1.666666e-11" ixy="0.0" ixz="0.0" iyy="1.666666e-11" iyz="0.0" izz="1.666666e-11"/>
    </inertial>
    <visual>
      <geometry>
        <cylinder length="0.000001" radius="0.0000001"/>
      </geometry>
      <origin rpy="0 0 0" xyz="0 0 0"/>
    </visual>
    <collision>
      <geometry>
        <cylinder length="0.0000001" radius="0.0000001"/>
      </geometry>
      <origin rpy="0 0 0" xyz="0 0 0"/>
    </collision>
  </link>
  <joint name="polysat/thruster_12_joint" type="continuous">
    <origin rpy="0 0 1.5707963268" xyz="0 0.5 0"/>
    <parent link="polysat/base_link"/>
    <child link="polysat/thruster_12"/>
    <axis xyz="1 0 0"/>
    <limit effort="0" lower="0" upper="0" velocity="0"/>
  </joint>
  <gazebo>
    <plugin filename="libsc_gazebo_thrust_plugin.so" name="polysat_12_thruster_model">
      <thruster>
        <linkName>polysat/thruster_12</linkName>
        <jointName>polysat/thruster_12_joint</jointName>
        <cmdTopic>polysat/thrusters/thruster_12</cmdTopic>
        <angleTopic>polysat/thrusters/thruster_12_angle</angleTopic>
        <enableAngle>false</enableAngle>
      </thruster>
    </plugin>
  </gazebo>
  <!-- <gazebo>
      <plugin name="${namespace}_${thruster_id}_thruster_model" filename="libLedPlugin.so">
        <light>
          <id>${namespace}/thruster_${thruster_id}/light</id>
          <block>
            <duration>1</duration>
            <interval>1</interval>
            <color>1 0.5 0.5</color>
          </block>
          <enable>true</enable>
        </light>
      </plugin>
    </gazebo> -->
  <!--gazebo reference="${namespace}/thruster_${thruster_id}">
      <xacro:led_stripe name="light_${thruster_id}" range="30" linear="0.2" constant="0.1" quadratic="0.0025"
        inner_angle="2.8" outer_angle="2.9" 
        pose="0 0 0 0 0 0"/>
    </gazebo-->
  <gazebo reference="polysat/thruster_12">
    <selfCollide>false</selfCollide>
  </gazebo>
  <link name="polysat/thruster_13">
    <inertial>
      <mass value="0.0001"/>
      <origin rpy="0 0 0" xyz="0 0 0"/>
      <inertia ixx="1.666666e-11" ixy="0.0" ixz="0.0" iyy="1.666666e-11" iyz="0.0" izz="1.666666e-11"/>
    </inertial>
    <visual>
      <geometry>
        <cylinder length="0.000001" radius="0.0000001"/>
      </geometry>
      <origin rpy="0 0 0" xyz="0 0 0"/>
    </visual>
    <collision>
      <geometry>
        <cylinder length="0.0000001" radius="0.0000001"/>
      </geometry>
      <origin rpy="0 0 0" xyz="0 0 0"/>
    </collision>
  </link>
  <joint name="polysat/thruster_13_joint" type="continuous">
    <origin rpy="0 0 -1.5707963268" xyz="0 -0.5 0"/>
    <parent link="polysat/base_link"/>
    <child link="polysat/thruster_13"/>
    <axis xyz="1 0 0"/>
    <limit effort="0" lower="0" upper="0" velocity="0"/>
  </joint>
  <gazebo>
    <plugin filename="libsc_gazebo_thrust_plugin.so" name="polysat_13_thruster_model">
      <thruster>
        <linkName>polysat/thruster_13</linkName>
        <jointName>polysat/thruster_13_joint</jointName>
        <cmdTopic>polysat/thrusters/thruster_13</cmdTopic>
        <angleTopic>polysat/thrusters/thruster_13_angle</angleTopic>
        <enableAngle>false</enableAngle>
      </thruster>
    </plugin>
  </gazebo>
  <!-- <gazebo>
      <plugin name="${namespace}_${thruster_id}_thruster_model" filename="libLedPlugin.so">
        <light>
          <id>${namespace}/thruster_${thruster_id}/light</id>
          <block>
            <duration>1</duration>
            <interval>1</interval>
            <color>1 0.5 0.5</color>
          </block>
          <enable>true</enable>
        </light>
      </plugin>
    </gazebo> -->
  <!--gazebo reference="${namespace}/thruster_${thruster_id}">
      <xacro:led_stripe name="light_${thruster_id}" range="30" linear="0.2" constant="0.1" quadratic="0.0025"
        inner_angle="2.8" outer_angle="2.9" 
        pose="0 0 0 0 0 0"/>
    </gazebo-->
  <gazebo reference="polysat/thruster_13">
    <selfCollide>false</selfCollide>
  </gazebo>
  <!-- IMU link -->
  <link name="polysat/imu_link">
    <inertial>
      <inertia ixx="0.00001" ixy="0.0" ixz="0.0" iyy="0.00001" iyz="0.0" izz="0.00001"/>
      <mass value="0.015"/>
      <!-- [kg] -->
      <origin rpy="0 0 0" xyz="0 0 0"/>
    </inertial>
  </link>
  <!-- IMU joint -->
  <joint name="polysat/imu_joint" type="revolute">
    <origin rpy="0 0 0" xyz="0 0 0"/>
    <parent link="polysat/base_link"/>
    <child link="polysat/imu_link"/>
    <limit effort="0" lower="0" upper="0" velocity="0"/>
    <axis xyz="1 0 0"/>
  </joint>
  <gazebo>
    <plugin filename="libsc_imu_gazebo_plugin.so" name="libsc_imu_gazebo_plugin">
      <!-- A good description of the IMU parameters can be found in the kalibr documentation:
           https://github.com/ethz-asl/kalibr/wiki/IMU-Noise-Model-and-Intrinsics -->
      <robot_namespace>polysat</robot_namespace>
      <!-- (string, required): ros namespace in which the messages are published -->
      <link_name>polysat/imu_link</link_name>
      <!-- (string, required): name of the body which holds the IMU sensor -->
      <sensor_topic>imu</sensor_topic>
      <!-- (string): name of the sensor output topic and prefix of service names (defaults to imu) -->
      <gyroscope_noise_density>0.0003394</gyroscope_noise_density>
      <!-- Gyroscope noise density (two-sided spectrum) [rad/s/sqrt(Hz)] -->
      <gyroscope_random_walk>3.8785e-05</gyroscope_random_walk>
      <!-- Gyroscope bias random walk [rad/s/s/sqrt(Hz)] -->
      <gyroscope_bias_correlation_time>1000.0</gyroscope_bias_correlation_time>
      <!-- Gyroscope bias correlation time constant [s] -->
      <gyroscope_turn_on_bias_sigma>0.0087</gyroscope_turn_on_bias_sigma>
      <!-- Gyroscope turn on bias standard deviation [rad/s] -->
      <accelerometer_noise_density>0.004</accelerometer_noise_density>
      <!-- Accelerometer noise density (two-sided spectrum) [m/s^2/sqrt(Hz)] -->
      <accelerometer_random_walk>0.006</accelerometer_random_walk>
      <!-- Accelerometer bias random walk. [m/s^2/s/sqrt(Hz)] -->
      <accelerometer_bias_correlation_time>300.0</accelerometer_bias_correlation_time>
      <!-- Accelerometer bias correlation time constant [s] -->
      <accelerometer_turn_on_bias_sigma>0.196</accelerometer_turn_on_bias_sigma>
      <!-- Accelerometer turn on bias standard deviation [m/s^2] -->
      <orientation_noise>0.01</orientation_noise>
      <update_rate>50</update_rate>
      <!-- Update period of accelerometer and gyroscope [s] -->
      <enable_gazebo_messages>false</enable_gazebo_messages>
      <enable_local_ned_frame>False</enable_local_ned_frame>
      <static_reference_frame>world</static_reference_frame>
    </plugin>
  </gazebo>
  <!--Mount a 3D pose sensor-->
  <link name="polysat/pose_sensor_link_default">
    <inertial>
      <inertia ixx="0.00001" ixy="0.0" ixz="0.0" iyy="0.00001" iyz="0.0" izz="0.00001"/>
      <mass value="0.001"/>
      <origin rpy="0 0 0" xyz="0 0 0"/>
    </inertial>
  </link>
  <joint name="polysat/pose_sensor_default_joint" type="revolute">
    <origin rpy="0 0 0" xyz="0 0 0"/>
    <axis xyz="0 0 1"/>
    <parent link="polysat/base_link"/>
    <child link="polysat/pose_sensor_link_default"/>
    <limit effort="0" lower="0" upper="0" velocity="0"/>
  </joint>
  <gazebo>
    <plugin filename="libsc_pose_gt_plugin.so" name="pose_3d_plugin">
      <robot_namespace>polysat</robot_namespace>
      <link_name>polysat/base_link</link_name>
      <sensor_topic>pose_gt</sensor_topic>
      <static_reference_frame>world</static_reference_frame>
      <noise_sigma>0.0</noise_sigma>
      <noise_amplitude>0.0</noise_amplitude>
      <update_rate>20</update_rate>
      <enable_gazebo_messages>false</enable_gazebo_messages>
      <publish_ned_odom>False</publish_ned_odom>
    </plugin>
  </gazebo>
  <!--xacro:include filename="$(find polysat_description)/urdf/polysat_sensors.xacro"/-->
  <!-- Base Link -->
  <link name="oberon7_r/base">
    <inertial>
      <origin rpy="0 0 0" xyz="-0.101581 -0.001371 -0.009781"/>
      <mass value="9.67467717018"/>
      <inertia ixx="0.511731678147" ixy="0.0" ixz="0.0" iyy="0.836771724144" iyz="0.0" izz="0.958032978152"/>
    </inertial>
    <visual>
      <origin rpy="0 0 0" xyz="0 0 0"/>
      <geometry>
        <mesh filename="package://oberon7_description/meshes/serial_arm/visual/Base.dae"/>
      </geometry>
    </visual>
    <collision>
      <origin rpy="0 0 0" xyz="0 0 0"/>
      <geometry>
        <mesh filename="package://oberon7_description/meshes/serial_arm/collision/Base.stl"/>
      </geometry>
    </collision>
  </link>
  <!-- Shoulder Link -->
  <link name="oberon7_r/shoulder_link">
    <inertial>
      <origin rpy="0 0 0" xyz="0.039670 0.005441 0.017383"/>
      <mass value="6.72225246901"/>
      <inertia ixx="0.425839738294" ixy="0.0" ixz="0.0" iyy="0.513257548564" iyz="0.0" izz="0.295765413777"/>
    </inertial>
    <visual>
      <origin rpy="0 0 0" xyz="0 0 0"/>
      <geometry>
        <mesh filename="package://oberon7_description/meshes/serial_arm/visual/ShoulderLink.dae"/>
      </geometry>
    </visual>
    <collision>
      <origin rpy="0 0 0" xyz="0.039670 0.005441 0.017383"/>
      <geometry>
        <cylinder length="0.239627" radius="0.068184"/>
      </geometry>
    </collision>
  </link>
  <!-- Base -> Shoulder Joint -->
  <joint name="oberon7_r/azimuth" type="revolute">
    <parent link="oberon7_r/base"/>
    <child link="oberon7_r/shoulder_link"/>
    <axis xyz="0 0 1"/>
    <dynamics damping="50" friction="120"/>
    <limit effort="200" lower="-1.04719758" upper="1.04719758" velocity="0.17"/>
  </joint>
  <!-- Upper Arm Link -->
  <link name="oberon7_r/upper_arm">
    <inertial>
      <origin rpy="0 0 0" xyz="0.312501 0.017478 -0.000002"/>
      <mass value="12.4443999072"/>
      <inertia ixx="0.378234483246" ixy="0.0" ixz="0.0" iyy="4.11488180504" iyz="0.0" izz="4.15420854645"/>
    </inertial>
    <visual>
      <origin rpy="0 0 0" xyz="0 0 0"/>
      <geometry>
        <mesh filename="package://oberon7_description/meshes/serial_arm/visual/UpperArm.dae"/>
      </geometry>
    </visual>
    <collision>
      <origin rpy="0 1.57079632679 0" xyz="0.312501 0.017478 -0.000002"/>
      <geometry>
        <cylinder length="0.616809" radius="0.0709445"/>
      </geometry>
    </collision>
  </link>
  <!-- Shoulder -> Upper Arm Joint -->
  <joint name="oberon7_r/shoulder" type="revolute">
    <parent link="oberon7_r/shoulder_link"/>
    <child link="oberon7_r/upper_arm"/>
    <origin rpy="1.57079632679 0 0" xyz="0.06955 0.00015 0.01536"/>
    <axis xyz="0 0 1"/>
    <dynamics damping="50" friction="120"/>
    <limit effort="5000" lower="-0.8591" upper="0.6856" velocity="0.17"/>
  </joint>
  <!-- Elbow Link -->
  <link name="oberon7_r/elbow_link">
    <inertial>
      <origin rpy="0 0 0" xyz="0.125269 -0.074675 0.0"/>
      <mass value="10.3145088675"/>
      <inertia ixx="0.717197873733" ixy="0.0" ixz="0.0" iyy="0.724090834438" iyz="0.0" izz="1.0276175034"/>
    </inertial>
    <visual>
      <origin rpy="0 0 0" xyz="0 0 0"/>
      <geometry>
        <mesh filename="package://oberon7_description/meshes/serial_arm/visual/ElbowLink.dae"/>
      </geometry>
    </visual>
    <collision>
      <origin rpy="0 1.57079632679 1.57079632679" xyz="0.125269 -0.074675 0.0"/>
      <geometry>
        <cylinder length="0.245312" radius="0.077562"/>
      </geometry>
    </collision>
  </link>
  <!-- Elbow -> Upper Arm Joint-->
  <joint name="oberon7_r/elbow" type="revolute">
    <parent link="oberon7_r/upper_arm"/>
    <child link="oberon7_r/elbow_link"/>
    <origin rpy="0 0 0" xyz="0.55616 -0.01229 0"/>
    <dynamics damping="50" friction="120"/>
    <axis xyz="0 0 1"/>
    <limit effort="300" lower="-1.4839" upper="1.04719758" velocity=".13"/>
  </joint>
  <!-- Forearm Link -->
  <link name="oberon7_r/forearm">
    <inertial>
      <origin rpy="0 0 0" xyz="0 0 0.157978803149"/>
      <mass value="8.54626175585"/>
      <inertia ixx="0.961794420773" ixy="0.0" ixz="0.0" iyy="0.961902303084" iyz="0.0" izz="0.326840256692"/>
    </inertial>
    <visual>
      <origin rpy="0 0 0" xyz="0 0 0"/>
      <geometry>
        <mesh filename="package://oberon7_description/meshes/serial_arm/visual/Forearm.dae"/>
      </geometry>
    </visual>
    <collision>
      <origin rpy="0 0 0" xyz="0 0 0.157978803149"/>
      <geometry>
        <cylinder length="0.334827" radius="0.0757275"/>
      </geometry>
    </collision>
  </link>
  <!-- Elbow -> Forearm Joint -->
  <joint name="oberon7_r/roll" type="revolute">
    <parent link="oberon7_r/elbow_link"/>
    <child link="oberon7_r/forearm"/>
    <origin rpy="1.57079632679 0 0" xyz="0.1349014 -0.1936267 0"/>
    <axis xyz="0 0 1"/>
    <dynamics damping="50" friction="120"/>
    <limit effort="200" lower="-2.356194555" upper="2.356194555" velocity=".085"/>
  </joint>
  <!-- Wrist Link -->
  <link name="oberon7_r/wrist_link">
    <inertial>
      <origin rpy="0 0 0" xyz="0.104016 0.003308 -0.000027"/>
      <mass value="3.9024235777"/>
      <inertia ixx="0.104282209379" ixy="0.0" ixz="0.0" iyy="0.211536636614" iyz="0.0" izz="0.20526721979"/>
    </inertial>
    <visual>
      <origin rpy="0 0 0" xyz="0 0 0"/>
      <geometry>
        <mesh filename="package://oberon7_description/meshes/serial_arm/visual/Wrist.dae"/>
      </geometry>
    </visual>
    <collision>
      <origin rpy="0 1.57079632679 0" xyz="0.104016 0.003308 -0.000027"/>
      <geometry>
        <cylinder length="0.219204" radius="0.065187"/>
      </geometry>
    </collision>
  </link>
  <!-- Forearm -> Wrist Joint -->
  <joint name="oberon7_r/pitch" type="revolute">
    <parent link="oberon7_r/forearm"/>
    <child link="oberon7_r/wrist_link"/>
    <origin rpy="-1.57079632679 -1.57079632679 0" xyz="0 0 0.31595760629823427"/>
    <axis xyz="0 0 1"/>
    <dynamics damping="50" friction="120"/>
    <limit effort="200" lower="-1.57079637" upper="1.57079637" velocity=".26"/>
  </joint>
  <!-- Ground Base -->
  <link name="oberon7_r/end_effector">
    <inertial>
      <origin rpy="0 0 0" xyz="0.024426 -0.000000 -0.000014"/>
      <mass value="3.46114581082"/>
      <inertia ixx="0.0774521740658" ixy="0.0" ixz="0.0" iyy="0.0536142648454" iyz="0.0" izz="0.055705568526"/>
    </inertial>
    <visual>
      <origin rpy="0 0 0" xyz="0 0 0"/>
      <geometry>
        <mesh filename="package://oberon7_description/meshes/parallel_gripper/visual/BaseGripper.dae"/>
      </geometry>
    </visual>
    <collision>
      <origin rpy="0 0 0" xyz="0.024426 -0.000000 -0.000014"/>
      <geometry>
        <box size="0.074326 0.117427 0.114298"/>
      </geometry>
    </collision>
  </link>
  <!-- Wrist -> End Effector Joint -->
  <joint name="oberon7_r/wrist" type="continuous">
    <parent link="oberon7_r/wrist_link"/>
    <child link="oberon7_r/end_effector"/>
    <origin rpy="0 0 0" xyz="0.19304 0 0"/>
    <axis xyz="1 0 0"/>
    <dynamics damping="10" friction="5"/>
  </joint>
  <!-- Finger Left -->
  <link name="oberon7_r/finger_left">
    <inertial>
      <origin rpy="0 0 0" xyz="0.025268 -0.001931 -0.000079"/>
      <mass value="0.879770511849"/>
      <inertia ixx="0.00378330605849" ixy="0.0" ixz="0.0" iyy="0.00886148330217" iyz="0.0" izz="0.0091923080428"/>
    </inertial>
    <visual>
      <origin rpy="0 0 0" xyz="0 0 0"/>
      <geometry>
        <mesh filename="package://oberon7_description/meshes/parallel_gripper/visual/Finger.dae"/>
      </geometry>
    </visual>
    <collision>
      <origin rpy="0 0 0" xyz="0 0 0"/>
      <geometry>
        <mesh filename="package://oberon7_description/meshes/parallel_gripper/visual/Finger.dae"/>
      </geometry>
      <surface>
        <friction>
          <ode>
            <mu>1000.0</mu>
            <mu2>1000.0</mu2>
          </ode>
        </friction>
      </surface>
    </collision>
  </link>
  <!-- End Effector -> Finger Left Joint -->
  <joint name="oberon7_r/finger_left_joint" type="revolute">
    <parent link="oberon7_r/end_effector"/>
    <child link="oberon7_r/finger_left"/>
    <origin rpy="0 0 0" xyz="0.0444267 0.0391376 0"/>
    <axis xyz="0 0 1"/>
    <dynamics damping="5" friction="10"/>
    <limit effort="3000" lower="0" upper="1.04709283144" velocity="0.15"/>
  </joint>
  <!-- Finger Tip Left  -->
  <link name="oberon7_r/finger_tip_left">
    <inertial>
      <origin rpy="0 0 0" xyz="0.027744 0.017278 0.0"/>
      <mass value="1.12550524054"/>
      <inertia ixx="0.00611047001819" ixy="0.0" ixz="0.0" iyy="0.0134903081039" iyz="0.0" izz="0.0121555609857"/>
    </inertial>
    <visual>
      <origin rpy="0 0 0" xyz="0 0 0"/>
      <geometry>
        <mesh filename="package://oberon7_description/meshes/parallel_gripper/visual/FingerTip.dae"/>
      </geometry>
    </visual>
    <collision>
      <origin rpy="0 0 0" xyz="0 0 0"/>
      <geometry>
        <mesh filename="package://oberon7_description/meshes/parallel_gripper/visual/FingerTip.dae"/>
      </geometry>
      <surface>
        <friction>
          <ode>
            <mu>1000.0</mu>
            <mu2>1000.0</mu2>
          </ode>
        </friction>
      </surface>
    </collision>
  </link>
  <!-- Finger -> Finger Tip Left Joint -->
  <joint name="oberon7_r/finger_tip_left_joint" type="revolute">
    <parent link="oberon7_r/finger_left"/>
    <child link="oberon7_r/finger_tip_left"/>
    <origin rpy="3.14159265359 0 0" xyz="0.06431 0 0"/>
    <axis xyz="0 0 1"/>
    <dynamics damping="5" friction="10"/>
    <limit effort="0" lower="0" upper="0" velocity="0"/>
  </joint>
  <!-- Finger Right -->
  <link name="oberon7_r/finger_right">
    <inertial>
      <origin rpy="0 0 0" xyz="0.025268 -0.001931 -0.000079"/>
      <mass value="0.879770511849"/>
      <inertia ixx="0.00378330605849" ixy="0.0" ixz="0.0" iyy="0.00886148330217" iyz="0.0" izz="0.0091923080428"/>
    </inertial>
    <visual>
      <origin rpy="0 0 0" xyz="0 0 0"/>
      <geometry>
        <mesh filename="package://oberon7_description/meshes/parallel_gripper/visual/Finger.dae"/>
      </geometry>
    </visual>
    <collision>
      <origin rpy="0 0 0" xyz="0 0 0"/>
      <geometry>
        <mesh filename="package://oberon7_description/meshes/parallel_gripper/visual/Finger.dae"/>
      </geometry>
      <surface>
        <friction>
          <ode>
            <mu>1000.0</mu>
            <mu2>1000.0</mu2>
          </ode>
        </friction>
      </surface>
    </collision>
  </link>
  <!-- End Effector -> Finger Right Joint -->
  <joint name="oberon7_r/finger_right_joint" type="revolute">
    <parent link="oberon7_r/end_effector"/>
    <child link="oberon7_r/finger_right"/>
    <origin rpy="3.14159265359 3.14159265359 3.14159265359" xyz="0.0444267 -0.0391376 0"/>
    <axis xyz="0 0 -1"/>
    <dynamics damping="5" friction="10"/>
    <limit effort="3000" lower="0" upper="1.04709283144" velocity="0.15"/>
  </joint>
  <!-- Finger Tip Right  -->
  <link name="oberon7_r/finger_tip_right">
    <inertial>
      <origin rpy="0 0 0" xyz="0.027744 0.017278 0.0"/>
      <mass value="1.12550524054"/>
      <inertia ixx="0.00611047001819" ixy="0.0" ixz="0.0" iyy="0.0134903081039" iyz="0.0" izz="0.0121555609857"/>
    </inertial>
    <visual>
      <origin rpy="0 0 0" xyz="0 0 0"/>
      <geometry>
        <mesh filename="package://oberon7_description/meshes/parallel_gripper/visual/FingerTip.dae"/>
      </geometry>
    </visual>
    <collision>
      <origin rpy="0 0 0" xyz="0 0 0"/>
      <geometry>
        <mesh filename="package://oberon7_description/meshes/parallel_gripper/visual/FingerTip.dae"/>
      </geometry>
      <surface>
        <friction>
          <ode>
            <mu>1000.0</mu>
            <mu2>1000.0</mu2>
          </ode>
        </friction>
      </surface>
    </collision>
  </link>
  <!-- Finger Right -> Finger Tip Right Joint -->
  <joint name="oberon7_r/finger_tip_right_joint" type="revolute">
    <parent link="oberon7_r/finger_right"/>
    <child link="oberon7_r/finger_tip_right"/>
    <origin rpy="0 0 0" xyz="0.06431 0 0"/>
    <axis xyz="0 0 1"/>
    <dynamics damping="5" friction="10"/>
    <limit effort="0" lower="0" upper="0" velocity="0"/>
  </joint>
  <!-- End of links and joints definitions -->
  <!-- Base -> Shoulder Transmission -->
  <transmission name="oberon7_r/azimuth_trans">
    <type>transmission_interface/SimpleTransmission</type>
    <joint name="oberon7_r/azimuth">
      <hardwareInterface>hardware_interface/EffortJointInterface</hardwareInterface>
    </joint>
    <actuator name="oberon7_r/azimuth_motor">
      <mechanicalReduction>1</mechanicalReduction>
    </actuator>
  </transmission>
  <!-- Shoulder -> Upper Arm Transmission -->
  <transmission name="oberon7_r/shoulder_trans">
    <type>transmission_interface/SimpleTransmission</type>
    <joint name="oberon7_r/shoulder">
      <hardwareInterface>hardware_interface/EffortJointInterface</hardwareInterface>
    </joint>
    <actuator name="oberon7_r/shoulder_motor">
      <mechanicalReduction>1</mechanicalReduction>
    </actuator>
  </transmission>
  <!-- Upper Arm -> Elbow Transmission -->
  <transmission name="oberon7_r/elbow_trans">
    <type>transmission_interface/SimpleTransmission</type>
    <joint name="oberon7_r/elbow">
      <hardwareInterface>hardware_interface/EffortJointInterface</hardwareInterface>
    </joint>
    <actuator name="oberon7_r/elbow_motor">
      <mechanicalReduction>1</mechanicalReduction>
    </actuator>
  </transmission>
  <!-- Elbow -> Forearm Transmission -->
  <transmission name="oberon7_r/roll_trans">
    <type>transmission_interface/SimpleTransmission</type>
    <joint name="oberon7_r/roll">
      <hardwareInterface>hardware_interface/EffortJointInterface</hardwareInterface>
    </joint>
    <actuator name="oberon7_r/roll_motor">
      <mechanicalReduction>1</mechanicalReduction>
    </actuator>
  </transmission>
  <!-- Forearm -> Wrist Transmission -->
  <transmission name="oberon7_r/pitch_trans">
    <type>transmission_interface/SimpleTransmission</type>
    <joint name="oberon7_r/pitch">
      <hardwareInterface>hardware_interface/EffortJointInterface</hardwareInterface>
    </joint>
    <actuator name="oberon7_r/pitch_motor">
      <mechanicalReduction>1</mechanicalReduction>
    </actuator>
  </transmission>
  <!-- Wrist -> End Effector Transmission -->
  <transmission name="oberon7_r/wrist_trans">
    <type>transmission_interface/SimpleTransmission</type>
    <joint name="oberon7_r/wrist">
      <hardwareInterface>hardware_interface/EffortJointInterface</hardwareInterface>
    </joint>
    <actuator name="oberon7_r/wrist_motor">
      <mechanicalReduction>1</mechanicalReduction>
    </actuator>
  </transmission>
  <!-- End Effector -> Finger Left Transmission -->
  <transmission name="oberon7_r/finger_left_joint_trans">
    <type>transmission_interface/SimpleTransmission</type>
    <joint name="oberon7_r/finger_left_joint">
      <hardwareInterface>hardware_interface/EffortJointInterface</hardwareInterface>
    </joint>
    <actuator name="oberon7_r/finger_left_joint_motor">
      <mechanicalReduction>1</mechanicalReduction>
    </actuator>
  </transmission>
  <!-- end Effector -> Finger Right Transmission -->
  <transmission name="oberon7_r/finger_right_joint_trans">
    <type>transmission_interface/SimpleTransmission</type>
    <joint name="oberon7_r/finger_right_joint">
      <hardwareInterface>hardware_interface/EffortJointInterface</hardwareInterface>
    </joint>
    <actuator name="oberon7_r/finger_right_joint_motor">
      <mechanicalReduction>1</mechanicalReduction>
    </actuator>
  </transmission>
  <!-- Finger Left -> Finger Tip Left Transmission -->
  <transmission name="oberon7_r/finger_tip_left_joint_trans">
    <type>transmission_interface/SimpleTransmission</type>
    <joint name="oberon7_r/finger_tip_left_joint">
      <hardwareInterface>hardware_interface/EffortJointInterface</hardwareInterface>
    </joint>
    <actuator name="oberon7_r/finger_tip_left_joint_motor">
      <mechanicalReduction>1</mechanicalReduction>
    </actuator>
  </transmission>
  <!-- Finger Right -> Finger Tip Right Transmission -->
  <transmission name="oberon7_r/finger_tip_right_joint_trans">
    <type>transmission_interface/SimpleTransmission</type>
    <joint name="oberon7_r/finger_tip_right_joint">
      <hardwareInterface>hardware_interface/EffortJointInterface</hardwareInterface>
    </joint>
    <actuator name="oberon7_r/finger_tip_right_joint_motor">
      <mechanicalReduction>1</mechanicalReduction>
    </actuator>
  </transmission>
  <gazebo reference="oberon7_r/base">
    <selfCollide>false</selfCollide>
    <maxContacts>1</maxContacts>
    <gravity>1</gravity>
  </gazebo>
  <gazebo reference="oberon7_r/shoulder_link">
    <selfCollide>false</selfCollide>
    <maxContacts>1</maxContacts>
    <gravity>1</gravity>
  </gazebo>
  <gazebo reference="oberon7_r/upper_arm">
    <selfCollide>false</selfCollide>
    <maxContacts>1</maxContacts>
    <gravity>1</gravity>
  </gazebo>
  <gazebo reference="oberon7_r/elbow_link">
    <selfCollide>false</selfCollide>
    <maxContacts>1</maxContacts>
    <gravity>1</gravity>
  </gazebo>
  <gazebo reference="oberon7_r/forearm">
    <selfCollide>false</selfCollide>
    <maxContacts>1</maxContacts>
    <gravity>1</gravity>
  </gazebo>
  <gazebo reference="oberon7_r/wrist_link">
    <selfCollide>false</selfCollide>
    <maxContacts>1</maxContacts>
    <gravity>1</gravity>
  </gazebo>
  <gazebo reference="oberon7_r/end_effector">
    <selfCollide>false</selfCollide>
    <maxContacts>1</maxContacts>
    <gravity>1</gravity>
  </gazebo>
  <gazebo reference="oberon7_r/finger_left">
    <selfCollide>false</selfCollide>
    <kp>1000000.0</kp>
    <kd>1.0</kd>
    <mu1>100.0</mu1>
    <mu2>50.0</mu2>
    <minDepth>0.001</minDepth>
    <maxContacts>1</maxContacts>
    <implicitSpringDamper>1</implicitSpringDamper>
  </gazebo>
  <gazebo reference="oberon7_r/finger_tip_left">
    <selfCollide>false</selfCollide>
    <kp>1000000.0</kp>
    <kd>1.0</kd>
    <mu1>100.0</mu1>
    <mu2>50.0</mu2>
    <minDepth>0.001</minDepth>
    <maxContacts>3</maxContacts>
    <implicitSpringDamper>1</implicitSpringDamper>
  </gazebo>
  <gazebo reference="oberon7_r/finger_right">
    <selfCollide>false</selfCollide>
    <kp>1000000.0</kp>
    <kd>1.0</kd>
    <mu1>100.0</mu1>
    <mu2>50.0</mu2>
    <minDepth>0.001</minDepth>
    <maxContacts>1</maxContacts>
    <implicitSpringDamper>1</implicitSpringDamper>
  </gazebo>
  <gazebo reference="oberon7_r/finger_tip_right">
    <selfCollide>false</selfCollide>
    <kp>1000000.0</kp>
    <kd>1.0</kd>
    <mu1>100.0</mu1>
    <mu2>50.0</mu2>
    <minDepth>0.001</minDepth>
    <maxContacts>3</maxContacts>
    <implicitSpringDamper>1</implicitSpringDamper>
  </gazebo>
  <!-- Base Link -->
  <link name="oberon7_l/base">
    <inertial>
      <origin rpy="0 0 0" xyz="-0.101581 -0.001371 -0.009781"/>
      <mass value="9.67467717018"/>
      <inertia ixx="0.511731678147" ixy="0.0" ixz="0.0" iyy="0.836771724144" iyz="0.0" izz="0.958032978152"/>
    </inertial>
    <visual>
      <origin rpy="0 0 0" xyz="0 0 0"/>
      <geometry>
        <mesh filename="package://oberon7_description/meshes/serial_arm/visual/Base.dae"/>
      </geometry>
    </visual>
    <collision>
      <origin rpy="0 0 0" xyz="0 0 0"/>
      <geometry>
        <mesh filename="package://oberon7_description/meshes/serial_arm/collision/Base.stl"/>
      </geometry>
    </collision>
  </link>
  <!-- Shoulder Link -->
  <link name="oberon7_l/shoulder_link">
    <inertial>
      <origin rpy="0 0 0" xyz="0.039670 0.005441 0.017383"/>
      <mass value="6.72225246901"/>
      <inertia ixx="0.425839738294" ixy="0.0" ixz="0.0" iyy="0.513257548564" iyz="0.0" izz="0.295765413777"/>
    </inertial>
    <visual>
      <origin rpy="0 0 0" xyz="0 0 0"/>
      <geometry>
        <mesh filename="package://oberon7_description/meshes/serial_arm/visual/ShoulderLink.dae"/>
      </geometry>
    </visual>
    <collision>
      <origin rpy="0 0 0" xyz="0.039670 0.005441 0.017383"/>
      <geometry>
        <cylinder length="0.239627" radius="0.068184"/>
      </geometry>
    </collision>
  </link>
  <!-- Base -> Shoulder Joint -->
  <joint name="oberon7_l/azimuth" type="revolute">
    <parent link="oberon7_l/base"/>
    <child link="oberon7_l/shoulder_link"/>
    <axis xyz="0 0 1"/>
    <dynamics damping="50" friction="120"/>
    <limit effort="200" lower="-1.04719758" upper="1.04719758" velocity="0.17"/>
  </joint>
  <!-- Upper Arm Link -->
  <link name="oberon7_l/upper_arm">
    <inertial>
      <origin rpy="0 0 0" xyz="0.312501 0.017478 -0.000002"/>
      <mass value="12.4443999072"/>
      <inertia ixx="0.378234483246" ixy="0.0" ixz="0.0" iyy="4.11488180504" iyz="0.0" izz="4.15420854645"/>
    </inertial>
    <visual>
      <origin rpy="0 0 0" xyz="0 0 0"/>
      <geometry>
        <mesh filename="package://oberon7_description/meshes/serial_arm/visual/UpperArm.dae"/>
      </geometry>
    </visual>
    <collision>
      <origin rpy="0 1.57079632679 0" xyz="0.312501 0.017478 -0.000002"/>
      <geometry>
        <cylinder length="0.616809" radius="0.0709445"/>
      </geometry>
    </collision>
  </link>
  <!-- Shoulder -> Upper Arm Joint -->
  <joint name="oberon7_l/shoulder" type="revolute">
    <parent link="oberon7_l/shoulder_link"/>
    <child link="oberon7_l/upper_arm"/>
    <origin rpy="1.57079632679 0 0" xyz="0.06955 0.00015 0.01536"/>
    <axis xyz="0 0 1"/>
    <dynamics damping="50" friction="120"/>
    <limit effort="5000" lower="-0.8591" upper="0.6856" velocity="0.17"/>
  </joint>
  <!-- Elbow Link -->
  <link name="oberon7_l/elbow_link">
    <inertial>
      <origin rpy="0 0 0" xyz="0.125269 -0.074675 0.0"/>
      <mass value="10.3145088675"/>
      <inertia ixx="0.717197873733" ixy="0.0" ixz="0.0" iyy="0.724090834438" iyz="0.0" izz="1.0276175034"/>
    </inertial>
    <visual>
      <origin rpy="0 0 0" xyz="0 0 0"/>
      <geometry>
        <mesh filename="package://oberon7_description/meshes/serial_arm/visual/ElbowLink.dae"/>
      </geometry>
    </visual>
    <collision>
      <origin rpy="0 1.57079632679 1.57079632679" xyz="0.125269 -0.074675 0.0"/>
      <geometry>
        <cylinder length="0.245312" radius="0.077562"/>
      </geometry>
    </collision>
  </link>
  <!-- Elbow -> Upper Arm Joint-->
  <joint name="oberon7_l/elbow" type="revolute">
    <parent link="oberon7_l/upper_arm"/>
    <child link="oberon7_l/elbow_link"/>
    <origin rpy="0 0 0" xyz="0.55616 -0.01229 0"/>
    <dynamics damping="50" friction="120"/>
    <axis xyz="0 0 1"/>
    <limit effort="300" lower="-1.4839" upper="1.04719758" velocity=".13"/>
  </joint>
  <!-- Forearm Link -->
  <link name="oberon7_l/forearm">
    <inertial>
      <origin rpy="0 0 0" xyz="0 0 0.157978803149"/>
      <mass value="8.54626175585"/>
      <inertia ixx="0.961794420773" ixy="0.0" ixz="0.0" iyy="0.961902303084" iyz="0.0" izz="0.326840256692"/>
    </inertial>
    <visual>
      <origin rpy="0 0 0" xyz="0 0 0"/>
      <geometry>
        <mesh filename="package://oberon7_description/meshes/serial_arm/visual/Forearm.dae"/>
      </geometry>
    </visual>
    <collision>
      <origin rpy="0 0 0" xyz="0 0 0.157978803149"/>
      <geometry>
        <cylinder length="0.334827" radius="0.0757275"/>
      </geometry>
    </collision>
  </link>
  <!-- Elbow -> Forearm Joint -->
  <joint name="oberon7_l/roll" type="revolute">
    <parent link="oberon7_l/elbow_link"/>
    <child link="oberon7_l/forearm"/>
    <origin rpy="1.57079632679 0 0" xyz="0.1349014 -0.1936267 0"/>
    <axis xyz="0 0 1"/>
    <dynamics damping="50" friction="120"/>
    <limit effort="200" lower="-2.356194555" upper="2.356194555" velocity=".085"/>
  </joint>
  <!-- Wrist Link -->
  <link name="oberon7_l/wrist_link">
    <inertial>
      <origin rpy="0 0 0" xyz="0.104016 0.003308 -0.000027"/>
      <mass value="3.9024235777"/>
      <inertia ixx="0.104282209379" ixy="0.0" ixz="0.0" iyy="0.211536636614" iyz="0.0" izz="0.20526721979"/>
    </inertial>
    <visual>
      <origin rpy="0 0 0" xyz="0 0 0"/>
      <geometry>
        <mesh filename="package://oberon7_description/meshes/serial_arm/visual/Wrist.dae"/>
      </geometry>
    </visual>
    <collision>
      <origin rpy="0 1.57079632679 0" xyz="0.104016 0.003308 -0.000027"/>
      <geometry>
        <cylinder length="0.219204" radius="0.065187"/>
      </geometry>
    </collision>
  </link>
  <!-- Forearm -> Wrist Joint -->
  <joint name="oberon7_l/pitch" type="revolute">
    <parent link="oberon7_l/forearm"/>
    <child link="oberon7_l/wrist_link"/>
    <origin rpy="-1.57079632679 -1.57079632679 0" xyz="0 0 0.31595760629823427"/>
    <axis xyz="0 0 1"/>
    <dynamics damping="50" friction="120"/>
    <limit effort="200" lower="-1.57079637" upper="1.57079637" velocity=".26"/>
  </joint>
  <!-- Ground Base -->
  <link name="oberon7_l/end_effector">
    <inertial>
      <origin rpy="0 0 0" xyz="0.024426 -0.000000 -0.000014"/>
      <mass value="3.46114581082"/>
      <inertia ixx="0.0774521740658" ixy="0.0" ixz="0.0" iyy="0.0536142648454" iyz="0.0" izz="0.055705568526"/>
    </inertial>
    <visual>
      <origin rpy="0 0 0" xyz="0 0 0"/>
      <geometry>
        <mesh filename="package://oberon7_description/meshes/parallel_gripper/visual/BaseGripper.dae"/>
      </geometry>
    </visual>
    <collision>
      <origin rpy="0 0 0" xyz="0.024426 -0.000000 -0.000014"/>
      <geometry>
        <box size="0.074326 0.117427 0.114298"/>
      </geometry>
    </collision>
  </link>
  <!-- Wrist -> End Effector Joint -->
  <joint name="oberon7_l/wrist" type="continuous">
    <parent link="oberon7_l/wrist_link"/>
    <child link="oberon7_l/end_effector"/>
    <origin rpy="0 0 0" xyz="0.19304 0 0"/>
    <axis xyz="1 0 0"/>
    <dynamics damping="10" friction="5"/>
  </joint>
  <!-- Finger Left -->
  <link name="oberon7_l/finger_left">
    <inertial>
      <origin rpy="0 0 0" xyz="0.025268 -0.001931 -0.000079"/>
      <mass value="0.879770511849"/>
      <inertia ixx="0.00378330605849" ixy="0.0" ixz="0.0" iyy="0.00886148330217" iyz="0.0" izz="0.0091923080428"/>
    </inertial>
    <visual>
      <origin rpy="0 0 0" xyz="0 0 0"/>
      <geometry>
        <mesh filename="package://oberon7_description/meshes/parallel_gripper/visual/Finger.dae"/>
      </geometry>
    </visual>
    <collision>
      <origin rpy="0 0 0" xyz="0 0 0"/>
      <geometry>
        <mesh filename="package://oberon7_description/meshes/parallel_gripper/visual/Finger.dae"/>
      </geometry>
      <surface>
        <friction>
          <ode>
            <mu>1000.0</mu>
            <mu2>1000.0</mu2>
          </ode>
        </friction>
      </surface>
    </collision>
  </link>
  <!-- End Effector -> Finger Left Joint -->
  <joint name="oberon7_l/finger_left_joint" type="revolute">
    <parent link="oberon7_l/end_effector"/>
    <child link="oberon7_l/finger_left"/>
    <origin rpy="0 0 0" xyz="0.0444267 0.0391376 0"/>
    <axis xyz="0 0 1"/>
    <dynamics damping="5" friction="10"/>
    <limit effort="3000" lower="0" upper="1.04709283144" velocity="0.15"/>
  </joint>
  <!-- Finger Tip Left  -->
  <link name="oberon7_l/finger_tip_left">
    <inertial>
      <origin rpy="0 0 0" xyz="0.027744 0.017278 0.0"/>
      <mass value="1.12550524054"/>
      <inertia ixx="0.00611047001819" ixy="0.0" ixz="0.0" iyy="0.0134903081039" iyz="0.0" izz="0.0121555609857"/>
    </inertial>
    <visual>
      <origin rpy="0 0 0" xyz="0 0 0"/>
      <geometry>
        <mesh filename="package://oberon7_description/meshes/parallel_gripper/visual/FingerTip.dae"/>
      </geometry>
    </visual>
    <collision>
      <origin rpy="0 0 0" xyz="0 0 0"/>
      <geometry>
        <mesh filename="package://oberon7_description/meshes/parallel_gripper/visual/FingerTip.dae"/>
      </geometry>
      <surface>
        <friction>
          <ode>
            <mu>1000.0</mu>
            <mu2>1000.0</mu2>
          </ode>
        </friction>
      </surface>
    </collision>
  </link>
  <!-- Finger -> Finger Tip Left Joint -->
  <joint name="oberon7_l/finger_tip_left_joint" type="revolute">
    <parent link="oberon7_l/finger_left"/>
    <child link="oberon7_l/finger_tip_left"/>
    <origin rpy="3.14159265359 0 0" xyz="0.06431 0 0"/>
    <axis xyz="0 0 1"/>
    <dynamics damping="5" friction="10"/>
    <limit effort="0" lower="0" upper="0" velocity="0"/>
  </joint>
  <!-- Finger Right -->
  <link name="oberon7_l/finger_right">
    <inertial>
      <origin rpy="0 0 0" xyz="0.025268 -0.001931 -0.000079"/>
      <mass value="0.879770511849"/>
      <inertia ixx="0.00378330605849" ixy="0.0" ixz="0.0" iyy="0.00886148330217" iyz="0.0" izz="0.0091923080428"/>
    </inertial>
    <visual>
      <origin rpy="0 0 0" xyz="0 0 0"/>
      <geometry>
        <mesh filename="package://oberon7_description/meshes/parallel_gripper/visual/Finger.dae"/>
      </geometry>
    </visual>
    <collision>
      <origin rpy="0 0 0" xyz="0 0 0"/>
      <geometry>
        <mesh filename="package://oberon7_description/meshes/parallel_gripper/visual/Finger.dae"/>
      </geometry>
      <surface>
        <friction>
          <ode>
            <mu>1000.0</mu>
            <mu2>1000.0</mu2>
          </ode>
        </friction>
      </surface>
    </collision>
  </link>
  <!-- End Effector -> Finger Right Joint -->
  <joint name="oberon7_l/finger_right_joint" type="revolute">
    <parent link="oberon7_l/end_effector"/>
    <child link="oberon7_l/finger_right"/>
    <origin rpy="3.14159265359 3.14159265359 3.14159265359" xyz="0.0444267 -0.0391376 0"/>
    <axis xyz="0 0 -1"/>
    <dynamics damping="5" friction="10"/>
    <limit effort="3000" lower="0" upper="1.04709283144" velocity="0.15"/>
  </joint>
  <!-- Finger Tip Right  -->
  <link name="oberon7_l/finger_tip_right">
    <inertial>
      <origin rpy="0 0 0" xyz="0.027744 0.017278 0.0"/>
      <mass value="1.12550524054"/>
      <inertia ixx="0.00611047001819" ixy="0.0" ixz="0.0" iyy="0.0134903081039" iyz="0.0" izz="0.0121555609857"/>
    </inertial>
    <visual>
      <origin rpy="0 0 0" xyz="0 0 0"/>
      <geometry>
        <mesh filename="package://oberon7_description/meshes/parallel_gripper/visual/FingerTip.dae"/>
      </geometry>
    </visual>
    <collision>
      <origin rpy="0 0 0" xyz="0 0 0"/>
      <geometry>
        <mesh filename="package://oberon7_description/meshes/parallel_gripper/visual/FingerTip.dae"/>
      </geometry>
      <surface>
        <friction>
          <ode>
            <mu>1000.0</mu>
            <mu2>1000.0</mu2>
          </ode>
        </friction>
      </surface>
    </collision>
  </link>
  <!-- Finger Right -> Finger Tip Right Joint -->
  <joint name="oberon7_l/finger_tip_right_joint" type="revolute">
    <parent link="oberon7_l/finger_right"/>
    <child link="oberon7_l/finger_tip_right"/>
    <origin rpy="0 0 0" xyz="0.06431 0 0"/>
    <axis xyz="0 0 1"/>
    <dynamics damping="5" friction="10"/>
    <limit effort="0" lower="0" upper="0" velocity="0"/>
  </joint>
  <!-- End of links and joints definitions -->
  <!-- Base -> Shoulder Transmission -->
  <transmission name="oberon7_l/azimuth_trans">
    <type>transmission_interface/SimpleTransmission</type>
    <joint name="oberon7_l/azimuth">
      <hardwareInterface>hardware_interface/EffortJointInterface</hardwareInterface>
    </joint>
    <actuator name="oberon7_l/azimuth_motor">
      <mechanicalReduction>1</mechanicalReduction>
    </actuator>
  </transmission>
  <!-- Shoulder -> Upper Arm Transmission -->
  <transmission name="oberon7_l/shoulder_trans">
    <type>transmission_interface/SimpleTransmission</type>
    <joint name="oberon7_l/shoulder">
      <hardwareInterface>hardware_interface/EffortJointInterface</hardwareInterface>
    </joint>
    <actuator name="oberon7_l/shoulder_motor">
      <mechanicalReduction>1</mechanicalReduction>
    </actuator>
  </transmission>
  <!-- Upper Arm -> Elbow Transmission -->
  <transmission name="oberon7_l/elbow_trans">
    <type>transmission_interface/SimpleTransmission</type>
    <joint name="oberon7_l/elbow">
      <hardwareInterface>hardware_interface/EffortJointInterface</hardwareInterface>
    </joint>
    <actuator name="oberon7_l/elbow_motor">
      <mechanicalReduction>1</mechanicalReduction>
    </actuator>
  </transmission>
  <!-- Elbow -> Forearm Transmission -->
  <transmission name="oberon7_l/roll_trans">
    <type>transmission_interface/SimpleTransmission</type>
    <joint name="oberon7_l/roll">
      <hardwareInterface>hardware_interface/EffortJointInterface</hardwareInterface>
    </joint>
    <actuator name="oberon7_l/roll_motor">
      <mechanicalReduction>1</mechanicalReduction>
    </actuator>
  </transmission>
  <!-- Forearm -> Wrist Transmission -->
  <transmission name="oberon7_l/pitch_trans">
    <type>transmission_interface/SimpleTransmission</type>
    <joint name="oberon7_l/pitch">
      <hardwareInterface>hardware_interface/EffortJointInterface</hardwareInterface>
    </joint>
    <actuator name="oberon7_l/pitch_motor">
      <mechanicalReduction>1</mechanicalReduction>
    </actuator>
  </transmission>
  <!-- Wrist -> End Effector Transmission -->
  <transmission name="oberon7_l/wrist_trans">
    <type>transmission_interface/SimpleTransmission</type>
    <joint name="oberon7_l/wrist">
      <hardwareInterface>hardware_interface/EffortJointInterface</hardwareInterface>
    </joint>
    <actuator name="oberon7_l/wrist_motor">
      <mechanicalReduction>1</mechanicalReduction>
    </actuator>
  </transmission>
  <!-- End Effector -> Finger Left Transmission -->
  <transmission name="oberon7_l/finger_left_joint_trans">
    <type>transmission_interface/SimpleTransmission</type>
    <joint name="oberon7_l/finger_left_joint">
      <hardwareInterface>hardware_interface/EffortJointInterface</hardwareInterface>
    </joint>
    <actuator name="oberon7_l/finger_left_joint_motor">
      <mechanicalReduction>1</mechanicalReduction>
    </actuator>
  </transmission>
  <!-- end Effector -> Finger Right Transmission -->
  <transmission name="oberon7_l/finger_right_joint_trans">
    <type>transmission_interface/SimpleTransmission</type>
    <joint name="oberon7_l/finger_right_joint">
      <hardwareInterface>hardware_interface/EffortJointInterface</hardwareInterface>
    </joint>
    <actuator name="oberon7_l/finger_right_joint_motor">
      <mechanicalReduction>1</mechanicalReduction>
    </actuator>
  </transmission>
  <!-- Finger Left -> Finger Tip Left Transmission -->
  <transmission name="oberon7_l/finger_tip_left_joint_trans">
    <type>transmission_interface/SimpleTransmission</type>
    <joint name="oberon7_l/finger_tip_left_joint">
      <hardwareInterface>hardware_interface/EffortJointInterface</hardwareInterface>
    </joint>
    <actuator name="oberon7_l/finger_tip_left_joint_motor">
      <mechanicalReduction>1</mechanicalReduction>
    </actuator>
  </transmission>
  <!-- Finger Right -> Finger Tip Right Transmission -->
  <transmission name="oberon7_l/finger_tip_right_joint_trans">
    <type>transmission_interface/SimpleTransmission</type>
    <joint name="oberon7_l/finger_tip_right_joint">
      <hardwareInterface>hardware_interface/EffortJointInterface</hardwareInterface>
    </joint>
    <actuator name="oberon7_l/finger_tip_right_joint_motor">
      <mechanicalReduction>1</mechanicalReduction>
    </actuator>
  </transmission>
  <gazebo reference="oberon7_l/base">
    <selfCollide>false</selfCollide>
    <maxContacts>1</maxContacts>
    <gravity>1</gravity>
  </gazebo>
  <gazebo reference="oberon7_l/shoulder_link">
    <selfCollide>false</selfCollide>
    <maxContacts>1</maxContacts>
    <gravity>1</gravity>
  </gazebo>
  <gazebo reference="oberon7_l/upper_arm">
    <selfCollide>false</selfCollide>
    <maxContacts>1</maxContacts>
    <gravity>1</gravity>
  </gazebo>
  <gazebo reference="oberon7_l/elbow_link">
    <selfCollide>false</selfCollide>
    <maxContacts>1</maxContacts>
    <gravity>1</gravity>
  </gazebo>
  <gazebo reference="oberon7_l/forearm">
    <selfCollide>false</selfCollide>
    <maxContacts>1</maxContacts>
    <gravity>1</gravity>
  </gazebo>
  <gazebo reference="oberon7_l/wrist_link">
    <selfCollide>false</selfCollide>
    <maxContacts>1</maxContacts>
    <gravity>1</gravity>
  </gazebo>
  <gazebo reference="oberon7_l/end_effector">
    <selfCollide>false</selfCollide>
    <maxContacts>1</maxContacts>
    <gravity>1</gravity>
  </gazebo>
  <gazebo reference="oberon7_l/finger_left">
    <selfCollide>false</selfCollide>
    <kp>1000000.0</kp>
    <kd>1.0</kd>
    <mu1>100.0</mu1>
    <mu2>50.0</mu2>
    <minDepth>0.001</minDepth>
    <maxContacts>1</maxContacts>
    <implicitSpringDamper>1</implicitSpringDamper>
  </gazebo>
  <gazebo reference="oberon7_l/finger_tip_left">
    <selfCollide>false</selfCollide>
    <kp>1000000.0</kp>
    <kd>1.0</kd>
    <mu1>100.0</mu1>
    <mu2>50.0</mu2>
    <minDepth>0.001</minDepth>
    <maxContacts>3</maxContacts>
    <implicitSpringDamper>1</implicitSpringDamper>
  </gazebo>
  <gazebo reference="oberon7_l/finger_right">
    <selfCollide>false</selfCollide>
    <kp>1000000.0</kp>
    <kd>1.0</kd>
    <mu1>100.0</mu1>
    <mu2>50.0</mu2>
    <minDepth>0.001</minDepth>
    <maxContacts>1</maxContacts>
    <implicitSpringDamper>1</implicitSpringDamper>
  </gazebo>
  <gazebo reference="oberon7_l/finger_tip_right">
    <selfCollide>false</selfCollide>
    <kp>1000000.0</kp>
    <kd>1.0</kd>
    <mu1>100.0</mu1>
    <mu2>50.0</mu2>
    <minDepth>0.001</minDepth>
    <maxContacts>3</maxContacts>
    <implicitSpringDamper>1</implicitSpringDamper>
  </gazebo>
  <joint name="oberon7_r_anchor" type="fixed">
    <parent link="polysat/base_link"/>
    <child link="oberon7_r/base"/>
    <origin rpy="-1.5707963268 0 0" xyz="0 1.5 0"/>
  </joint>
  <joint name="oberon7_l_anchor" type="fixed">
    <parent link="polysat/base_link"/>
    <child link="oberon7_l/base"/>
    <origin rpy="1.5707963268 0 0" xyz="0 -1.5 0"/>
  </joint>
</robot>

