<?xml version="1.0" ?>
<!-- =================================================================================== -->
<!-- |    This document was autogenerated by xacro from polysat_robot.urdf.xacro       | -->
<!-- |    EDITING THIS FILE BY HAND IS NOT RECOMMENDED                                 | -->
<!-- =================================================================================== -->
<robot name="polysat">
  <!-- "Dummy base link to eliminate root link inertia warning -->
  <link name="polysat/base_link"/>
  <!-- Start of main robot body -->
  <link name="polysat/polysat_link">
    <inertial>
      <origin rpy="0 0 0" xyz="0 0 0"/>
      <mass value="50.0"/>
      <inertia ixx="10.0" ixy="0.0" ixz="0.0" iyy="10.0" iyz="0.0" izz="10.0"/>
    </inertial>
    <visual>
      <origin rpy="1.570796326794 0 0" xyz="-0.5 1.0 -0.5"/>
      <geometry>
        <mesh filename="file:///home/carson/spaceship_ws/src/spacecraft_sim/urdf/robots/polysat_description/meshes/base.stl" scale="0.001 0.001 0.001"/>
      </geometry>
    </visual>
    <collision>
      <origin rpy="1.570796326794 0 0" xyz="-0.5 1.0 -0.5"/>
      <geometry>
        <mesh filename="file:///home/carson/spaceship_ws/src/spacecraft_sim/urdf/robots/polysat_description/meshes/base.stl" scale="0.001 0.001 0.001"/>
      </geometry>
    </collision>
  </link>
  <link name="polysat/thruster_0_visual">
    <inertial>
      <mass value="0.0001"/>
      <origin rpy="0 0 0" xyz="0 0 0"/>
      <inertia ixx="1.666666e-11" ixy="0.0" ixz="0.0" iyy="1.666666e-11" iyz="0.0" izz="1.666666e-11"/>
    </inertial>
    <visual>
      <origin rpy="0 0 0" xyz="0 0 0"/>
      <geometry>
        <mesh filename="file:///home/carson/spaceship_ws/src/spacecraft_sim/urdf/robots/polysat_description/meshes/thruster.stl" scale="0.001 0.001 0.001"/>
      </geometry>
    </visual>
    <collision>
      <origin rpy="0 0 0" xyz="0 0 0"/>
      <geometry>
        <mesh filename="file:///home/carson/spaceship_ws/src/spacecraft_sim/urdf/robots/polysat_description/meshes/thruster.stl" scale="0.001 0.001 0.001"/>
      </geometry>
    </collision>
  </link>
  <joint name="polysat/thruster_0_visual_joint" type="fixed">
    <origin rpy="0 0 0" xyz="0.355 -0.075 0.5"/>
    <parent link="polysat/base_link"/>
    <child link="polysat/thruster_0_visual"/>
  </joint>
  <link name="polysat/thrust_plume_0_visual">
    <inertial>
      <mass value="0.0001"/>
      <origin rpy="0 0 0" xyz="0 0 0"/>
      <inertia ixx="1.666666e-11" ixy="0.0" ixz="0.0" iyy="1.666666e-11" iyz="0.0" izz="1.666666e-11"/>
    </inertial>
    <visual>
      <origin rpy="0 0 0" xyz="0 0 0"/>
      <geometry>
        <mesh filename="file:///home/carson/spaceship_ws/src/spacecraft_sim/urdf/robots/polysat_description/meshes/thrust_plume.stl" scale="0.001 0.001 0.001"/>
      </geometry>
      <plugin filename="libsc_led_visual_plugin.so" name="blink">
        <color_a>1 0 0 1</color_a>
        <color_b>1 0 0 0</color_b>
        <period>1</period>
      </plugin>
    </visual>
    <collision>
      <origin rpy="0 0 0" xyz="0 0 0"/>
      <geometry>
        <mesh filename="file:///home/carson/spaceship_ws/src/spacecraft_sim/urdf/robots/polysat_description/meshes/thrust_plume.stl" scale="0.001 0.001 0.001"/>
      </geometry>
    </collision>
  </link>
  <joint name="polysat/thrust_plume_0_visual_joint" type="fixed">
    <origin rpy="1.5707963267948966 0 0" xyz="0.265 0.165 0.55"/>
    <parent link="polysat/base_link"/>
    <child link="polysat/thrust_plume_0_visual"/>
  </joint>
  <!-- Add thruster meshes >
    <link name="$(arg namespace)/thruster__visual_link">
      <inertial>
        <origin xyz="0 0 0" rpy="0 0 0"/>
        <mass value="0.00001"/>
        <inertia
          ixx="0.0001" ixy="0.0" ixz="0.0"
          iyy="0.0001" iyz="0.0"
          izz="0.0001"/>
      </inertial>
      <visual>
        <origin xyz="0 0 0" rpy="0 0 0"/>
        <geometry>
          <mesh filename="file://$(find polysat_description)/meshes/thruster.stl" scale="0.001 0.001 0.001"/>
        </geometry>
      </visual>
      <collision>
        <origin xyz="0 0 0" rpy="0 0 0"/>
        <geometry>
          <mesh filename="file://$(find polysat_description)/meshes/thruster.stl" scale="0.001 0.001 0.001"/>
        </geometry>
      </collision>
    </link>
        
    <joint name="$(arg namespace)/thruster__visual_joint" type="fixed">
      <origin xyz="${0.5-0.15} ${-0.15/2} 0.5" rpy="0 0 0"/>
      <parent link="$(arg namespace)/base_link"/>
      <child link="$(arg namespace)/thruster__visual_link"/>
    </joint-->
  <!-- Connect dummy link to main link -->
  <joint name="polysat/polysat_base_joint" type="fixed">
    <origin rpy="0 0 0" xyz="0 0 0"/>
    <parent link="polysat/base_link"/>
    <child link="polysat/polysat_link"/>
  </joint>
  <gazebo>
    <plugin filename="libgazebo_ros_control.so" name="gazebo_ros_control">
      <robotNamespace>polysat</robotNamespace>
      <robotParam>polysat</robotParam>
    </plugin>
  </gazebo>
  <link name="polysat/thruster_0">
    <inertial>
      <mass value="0.0001"/>
      <origin rpy="0 0 0" xyz="0 0 0"/>
      <inertia ixx="1.666666e-11" ixy="0.0" ixz="0.0" iyy="1.666666e-11" iyz="0.0" izz="1.666666e-11"/>
    </inertial>
    <visual>
      <geometry>
        <cylinder length="0.000001" radius="0.0000001"/>
      </geometry>
      <origin rpy="0 0 0" xyz="0 0 0"/>
    </visual>
    <collision>
      <geometry>
        <cylinder length="0.0000001" radius="0.0000001"/>
      </geometry>
      <origin rpy="0 0 0" xyz="0 0 0"/>
    </collision>
  </link>
  <joint name="polysat/thruster_0_joint" type="continuous">
    <origin rpy="0 0 0" xyz="0.5 0 0.5"/>
    <parent link="polysat/base_link"/>
    <child link="polysat/thruster_0"/>
    <axis xyz="1 0 0"/>
    <limit effort="0" lower="0" upper="0" velocity="0"/>
  </joint>
  <gazebo>
    <plugin filename="libsc_gazebo_thrust_plugin.so" name="polysat_0_thruster_model">
      <thruster>
        <linkName>polysat/thruster_0</linkName>
        <jointName>polysat/thruster_0_joint</jointName>
        <cmdTopic>polysat/thrusters/thruster_0</cmdTopic>
        <angleTopic>polysat/thrusters/thruster_0_angle</angleTopic>
        <enableAngle>false</enableAngle>
      </thruster>
    </plugin>
  </gazebo>
  <!-- <gazebo>
      <plugin name="${namespace}_${thruster_id}_thruster_model" filename="libLedPlugin.so">
        <light>
          <id>${namespace}/thruster_${thruster_id}/light</id>
          <block>
            <duration>1</duration>
            <interval>1</interval>
            <color>1 0.5 0.5</color>
          </block>
          <enable>true</enable>
        </light>
      </plugin>
    </gazebo> -->
  <!--gazebo reference="${namespace}/thruster_${thruster_id}">
      <xacro:led_stripe name="light_${thruster_id}" range="30" linear="0.2" constant="0.1" quadratic="0.0025"
        inner_angle="2.8" outer_angle="2.9" 
        pose="0 0 0 0 0 0"/>
    </gazebo-->
  <gazebo reference="polysat/thruster_0">
    <selfCollide>false</selfCollide>
  </gazebo>
  <link name="polysat/thruster_1">
    <inertial>
      <mass value="0.0001"/>
      <origin rpy="0 0 0" xyz="0 0 0"/>
      <inertia ixx="1.666666e-11" ixy="0.0" ixz="0.0" iyy="1.666666e-11" iyz="0.0" izz="1.666666e-11"/>
    </inertial>
    <visual>
      <geometry>
        <cylinder length="0.000001" radius="0.0000001"/>
      </geometry>
      <origin rpy="0 0 0" xyz="0 0 0"/>
    </visual>
    <collision>
      <geometry>
        <cylinder length="0.0000001" radius="0.0000001"/>
      </geometry>
      <origin rpy="0 0 0" xyz="0 0 0"/>
    </collision>
  </link>
  <joint name="polysat/thruster_1_joint" type="continuous">
    <origin rpy="0 0 0" xyz="0.5 0 -0.5"/>
    <parent link="polysat/base_link"/>
    <child link="polysat/thruster_1"/>
    <axis xyz="1 0 0"/>
    <limit effort="0" lower="0" upper="0" velocity="0"/>
  </joint>
  <gazebo>
    <plugin filename="libsc_gazebo_thrust_plugin.so" name="polysat_1_thruster_model">
      <thruster>
        <linkName>polysat/thruster_1</linkName>
        <jointName>polysat/thruster_1_joint</jointName>
        <cmdTopic>polysat/thrusters/thruster_1</cmdTopic>
        <angleTopic>polysat/thrusters/thruster_1_angle</angleTopic>
        <enableAngle>false</enableAngle>
      </thruster>
    </plugin>
  </gazebo>
  <!-- <gazebo>
      <plugin name="${namespace}_${thruster_id}_thruster_model" filename="libLedPlugin.so">
        <light>
          <id>${namespace}/thruster_${thruster_id}/light</id>
          <block>
            <duration>1</duration>
            <interval>1</interval>
            <color>1 0.5 0.5</color>
          </block>
          <enable>true</enable>
        </light>
      </plugin>
    </gazebo> -->
  <!--gazebo reference="${namespace}/thruster_${thruster_id}">
      <xacro:led_stripe name="light_${thruster_id}" range="30" linear="0.2" constant="0.1" quadratic="0.0025"
        inner_angle="2.8" outer_angle="2.9" 
        pose="0 0 0 0 0 0"/>
    </gazebo-->
  <gazebo reference="polysat/thruster_1">
    <selfCollide>false</selfCollide>
  </gazebo>
  <link name="polysat/thruster_2">
    <inertial>
      <mass value="0.0001"/>
      <origin rpy="0 0 0" xyz="0 0 0"/>
      <inertia ixx="1.666666e-11" ixy="0.0" ixz="0.0" iyy="1.666666e-11" iyz="0.0" izz="1.666666e-11"/>
    </inertial>
    <visual>
      <geometry>
        <cylinder length="0.000001" radius="0.0000001"/>
      </geometry>
      <origin rpy="0 0 0" xyz="0 0 0"/>
    </visual>
    <collision>
      <geometry>
        <cylinder length="0.0000001" radius="0.0000001"/>
      </geometry>
      <origin rpy="0 0 0" xyz="0 0 0"/>
    </collision>
  </link>
  <joint name="polysat/thruster_2_joint" type="continuous">
    <origin rpy="0 0 3.1415926535" xyz="-0.5 0 0.5"/>
    <parent link="polysat/base_link"/>
    <child link="polysat/thruster_2"/>
    <axis xyz="1 0 0"/>
    <limit effort="0" lower="0" upper="0" velocity="0"/>
  </joint>
  <gazebo>
    <plugin filename="libsc_gazebo_thrust_plugin.so" name="polysat_2_thruster_model">
      <thruster>
        <linkName>polysat/thruster_2</linkName>
        <jointName>polysat/thruster_2_joint</jointName>
        <cmdTopic>polysat/thrusters/thruster_2</cmdTopic>
        <angleTopic>polysat/thrusters/thruster_2_angle</angleTopic>
        <enableAngle>false</enableAngle>
      </thruster>
    </plugin>
  </gazebo>
  <!-- <gazebo>
      <plugin name="${namespace}_${thruster_id}_thruster_model" filename="libLedPlugin.so">
        <light>
          <id>${namespace}/thruster_${thruster_id}/light</id>
          <block>
            <duration>1</duration>
            <interval>1</interval>
            <color>1 0.5 0.5</color>
          </block>
          <enable>true</enable>
        </light>
      </plugin>
    </gazebo> -->
  <!--gazebo reference="${namespace}/thruster_${thruster_id}">
      <xacro:led_stripe name="light_${thruster_id}" range="30" linear="0.2" constant="0.1" quadratic="0.0025"
        inner_angle="2.8" outer_angle="2.9" 
        pose="0 0 0 0 0 0"/>
    </gazebo-->
  <gazebo reference="polysat/thruster_2">
    <selfCollide>false</selfCollide>
  </gazebo>
  <link name="polysat/thruster_3">
    <inertial>
      <mass value="0.0001"/>
      <origin rpy="0 0 0" xyz="0 0 0"/>
      <inertia ixx="1.666666e-11" ixy="0.0" ixz="0.0" iyy="1.666666e-11" iyz="0.0" izz="1.666666e-11"/>
    </inertial>
    <visual>
      <geometry>
        <cylinder length="0.000001" radius="0.0000001"/>
      </geometry>
      <origin rpy="0 0 0" xyz="0 0 0"/>
    </visual>
    <collision>
      <geometry>
        <cylinder length="0.0000001" radius="0.0000001"/>
      </geometry>
      <origin rpy="0 0 0" xyz="0 0 0"/>
    </collision>
  </link>
  <joint name="polysat/thruster_3_joint" type="continuous">
    <origin rpy="0 0 3.1415926535" xyz="-0.5 0 -0.5"/>
    <parent link="polysat/base_link"/>
    <child link="polysat/thruster_3"/>
    <axis xyz="1 0 0"/>
    <limit effort="0" lower="0" upper="0" velocity="0"/>
  </joint>
  <gazebo>
    <plugin filename="libsc_gazebo_thrust_plugin.so" name="polysat_3_thruster_model">
      <thruster>
        <linkName>polysat/thruster_3</linkName>
        <jointName>polysat/thruster_3_joint</jointName>
        <cmdTopic>polysat/thrusters/thruster_3</cmdTopic>
        <angleTopic>polysat/thrusters/thruster_3_angle</angleTopic>
        <enableAngle>false</enableAngle>
      </thruster>
    </plugin>
  </gazebo>
  <!-- <gazebo>
      <plugin name="${namespace}_${thruster_id}_thruster_model" filename="libLedPlugin.so">
        <light>
          <id>${namespace}/thruster_${thruster_id}/light</id>
          <block>
            <duration>1</duration>
            <interval>1</interval>
            <color>1 0.5 0.5</color>
          </block>
          <enable>true</enable>
        </light>
      </plugin>
    </gazebo> -->
  <!--gazebo reference="${namespace}/thruster_${thruster_id}">
      <xacro:led_stripe name="light_${thruster_id}" range="30" linear="0.2" constant="0.1" quadratic="0.0025"
        inner_angle="2.8" outer_angle="2.9" 
        pose="0 0 0 0 0 0"/>
    </gazebo-->
  <gazebo reference="polysat/thruster_3">
    <selfCollide>false</selfCollide>
  </gazebo>
  <link name="polysat/thruster_4">
    <inertial>
      <mass value="0.0001"/>
      <origin rpy="0 0 0" xyz="0 0 0"/>
      <inertia ixx="1.666666e-11" ixy="0.0" ixz="0.0" iyy="1.666666e-11" iyz="0.0" izz="1.666666e-11"/>
    </inertial>
    <visual>
      <geometry>
        <cylinder length="0.000001" radius="0.0000001"/>
      </geometry>
      <origin rpy="0 0 0" xyz="0 0 0"/>
    </visual>
    <collision>
      <geometry>
        <cylinder length="0.0000001" radius="0.0000001"/>
      </geometry>
      <origin rpy="0 0 0" xyz="0 0 0"/>
    </collision>
  </link>
  <joint name="polysat/thruster_4_joint" type="continuous">
    <origin rpy="0 -1.5707963268 0" xyz="0 0.5 0.5"/>
    <parent link="polysat/base_link"/>
    <child link="polysat/thruster_4"/>
    <axis xyz="1 0 0"/>
    <limit effort="0" lower="0" upper="0" velocity="0"/>
  </joint>
  <gazebo>
    <plugin filename="libsc_gazebo_thrust_plugin.so" name="polysat_4_thruster_model">
      <thruster>
        <linkName>polysat/thruster_4</linkName>
        <jointName>polysat/thruster_4_joint</jointName>
        <cmdTopic>polysat/thrusters/thruster_4</cmdTopic>
        <angleTopic>polysat/thrusters/thruster_4_angle</angleTopic>
        <enableAngle>false</enableAngle>
      </thruster>
    </plugin>
  </gazebo>
  <!-- <gazebo>
      <plugin name="${namespace}_${thruster_id}_thruster_model" filename="libLedPlugin.so">
        <light>
          <id>${namespace}/thruster_${thruster_id}/light</id>
          <block>
            <duration>1</duration>
            <interval>1</interval>
            <color>1 0.5 0.5</color>
          </block>
          <enable>true</enable>
        </light>
      </plugin>
    </gazebo> -->
  <!--gazebo reference="${namespace}/thruster_${thruster_id}">
      <xacro:led_stripe name="light_${thruster_id}" range="30" linear="0.2" constant="0.1" quadratic="0.0025"
        inner_angle="2.8" outer_angle="2.9" 
        pose="0 0 0 0 0 0"/>
    </gazebo-->
  <gazebo reference="polysat/thruster_4">
    <selfCollide>false</selfCollide>
  </gazebo>
  <link name="polysat/thruster_5">
    <inertial>
      <mass value="0.0001"/>
      <origin rpy="0 0 0" xyz="0 0 0"/>
      <inertia ixx="1.666666e-11" ixy="0.0" ixz="0.0" iyy="1.666666e-11" iyz="0.0" izz="1.666666e-11"/>
    </inertial>
    <visual>
      <geometry>
        <cylinder length="0.000001" radius="0.0000001"/>
      </geometry>
      <origin rpy="0 0 0" xyz="0 0 0"/>
    </visual>
    <collision>
      <geometry>
        <cylinder length="0.0000001" radius="0.0000001"/>
      </geometry>
      <origin rpy="0 0 0" xyz="0 0 0"/>
    </collision>
  </link>
  <joint name="polysat/thruster_5_joint" type="continuous">
    <origin rpy="0 -1.5707963268 0" xyz="0 -0.5 0.5"/>
    <parent link="polysat/base_link"/>
    <child link="polysat/thruster_5"/>
    <axis xyz="1 0 0"/>
    <limit effort="0" lower="0" upper="0" velocity="0"/>
  </joint>
  <gazebo>
    <plugin filename="libsc_gazebo_thrust_plugin.so" name="polysat_5_thruster_model">
      <thruster>
        <linkName>polysat/thruster_5</linkName>
        <jointName>polysat/thruster_5_joint</jointName>
        <cmdTopic>polysat/thrusters/thruster_5</cmdTopic>
        <angleTopic>polysat/thrusters/thruster_5_angle</angleTopic>
        <enableAngle>false</enableAngle>
      </thruster>
    </plugin>
  </gazebo>
  <!-- <gazebo>
      <plugin name="${namespace}_${thruster_id}_thruster_model" filename="libLedPlugin.so">
        <light>
          <id>${namespace}/thruster_${thruster_id}/light</id>
          <block>
            <duration>1</duration>
            <interval>1</interval>
            <color>1 0.5 0.5</color>
          </block>
          <enable>true</enable>
        </light>
      </plugin>
    </gazebo> -->
  <!--gazebo reference="${namespace}/thruster_${thruster_id}">
      <xacro:led_stripe name="light_${thruster_id}" range="30" linear="0.2" constant="0.1" quadratic="0.0025"
        inner_angle="2.8" outer_angle="2.9" 
        pose="0 0 0 0 0 0"/>
    </gazebo-->
  <gazebo reference="polysat/thruster_5">
    <selfCollide>false</selfCollide>
  </gazebo>
  <link name="polysat/thruster_6">
    <inertial>
      <mass value="0.0001"/>
      <origin rpy="0 0 0" xyz="0 0 0"/>
      <inertia ixx="1.666666e-11" ixy="0.0" ixz="0.0" iyy="1.666666e-11" iyz="0.0" izz="1.666666e-11"/>
    </inertial>
    <visual>
      <geometry>
        <cylinder length="0.000001" radius="0.0000001"/>
      </geometry>
      <origin rpy="0 0 0" xyz="0 0 0"/>
    </visual>
    <collision>
      <geometry>
        <cylinder length="0.0000001" radius="0.0000001"/>
      </geometry>
      <origin rpy="0 0 0" xyz="0 0 0"/>
    </collision>
  </link>
  <joint name="polysat/thruster_6_joint" type="continuous">
    <origin rpy="0 1.5707963268 0" xyz="0 0.5 -0.5"/>
    <parent link="polysat/base_link"/>
    <child link="polysat/thruster_6"/>
    <axis xyz="1 0 0"/>
    <limit effort="0" lower="0" upper="0" velocity="0"/>
  </joint>
  <gazebo>
    <plugin filename="libsc_gazebo_thrust_plugin.so" name="polysat_6_thruster_model">
      <thruster>
        <linkName>polysat/thruster_6</linkName>
        <jointName>polysat/thruster_6_joint</jointName>
        <cmdTopic>polysat/thrusters/thruster_6</cmdTopic>
        <angleTopic>polysat/thrusters/thruster_6_angle</angleTopic>
        <enableAngle>false</enableAngle>
      </thruster>
    </plugin>
  </gazebo>
  <!-- <gazebo>
      <plugin name="${namespace}_${thruster_id}_thruster_model" filename="libLedPlugin.so">
        <light>
          <id>${namespace}/thruster_${thruster_id}/light</id>
          <block>
            <duration>1</duration>
            <interval>1</interval>
            <color>1 0.5 0.5</color>
          </block>
          <enable>true</enable>
        </light>
      </plugin>
    </gazebo> -->
  <!--gazebo reference="${namespace}/thruster_${thruster_id}">
      <xacro:led_stripe name="light_${thruster_id}" range="30" linear="0.2" constant="0.1" quadratic="0.0025"
        inner_angle="2.8" outer_angle="2.9" 
        pose="0 0 0 0 0 0"/>
    </gazebo-->
  <gazebo reference="polysat/thruster_6">
    <selfCollide>false</selfCollide>
  </gazebo>
  <link name="polysat/thruster_7">
    <inertial>
      <mass value="0.0001"/>
      <origin rpy="0 0 0" xyz="0 0 0"/>
      <inertia ixx="1.666666e-11" ixy="0.0" ixz="0.0" iyy="1.666666e-11" iyz="0.0" izz="1.666666e-11"/>
    </inertial>
    <visual>
      <geometry>
        <cylinder length="0.000001" radius="0.0000001"/>
      </geometry>
      <origin rpy="0 0 0" xyz="0 0 0"/>
    </visual>
    <collision>
      <geometry>
        <cylinder length="0.0000001" radius="0.0000001"/>
      </geometry>
      <origin rpy="0 0 0" xyz="0 0 0"/>
    </collision>
  </link>
  <joint name="polysat/thruster_7_joint" type="continuous">
    <origin rpy="0 1.5707963268 0" xyz="0 -0.5 -0.5"/>
    <parent link="polysat/base_link"/>
    <child link="polysat/thruster_7"/>
    <axis xyz="1 0 0"/>
    <limit effort="0" lower="0" upper="0" velocity="0"/>
  </joint>
  <gazebo>
    <plugin filename="libsc_gazebo_thrust_plugin.so" name="polysat_7_thruster_model">
      <thruster>
        <linkName>polysat/thruster_7</linkName>
        <jointName>polysat/thruster_7_joint</jointName>
        <cmdTopic>polysat/thrusters/thruster_7</cmdTopic>
        <angleTopic>polysat/thrusters/thruster_7_angle</angleTopic>
        <enableAngle>false</enableAngle>
      </thruster>
    </plugin>
  </gazebo>
  <!-- <gazebo>
      <plugin name="${namespace}_${thruster_id}_thruster_model" filename="libLedPlugin.so">
        <light>
          <id>${namespace}/thruster_${thruster_id}/light</id>
          <block>
            <duration>1</duration>
            <interval>1</interval>
            <color>1 0.5 0.5</color>
          </block>
          <enable>true</enable>
        </light>
      </plugin>
    </gazebo> -->
  <!--gazebo reference="${namespace}/thruster_${thruster_id}">
      <xacro:led_stripe name="light_${thruster_id}" range="30" linear="0.2" constant="0.1" quadratic="0.0025"
        inner_angle="2.8" outer_angle="2.9" 
        pose="0 0 0 0 0 0"/>
    </gazebo-->
  <gazebo reference="polysat/thruster_7">
    <selfCollide>false</selfCollide>
  </gazebo>
  <link name="polysat/thruster_8">
    <inertial>
      <mass value="0.0001"/>
      <origin rpy="0 0 0" xyz="0 0 0"/>
      <inertia ixx="1.666666e-11" ixy="0.0" ixz="0.0" iyy="1.666666e-11" iyz="0.0" izz="1.666666e-11"/>
    </inertial>
    <visual>
      <geometry>
        <cylinder length="0.000001" radius="0.0000001"/>
      </geometry>
      <origin rpy="0 0 0" xyz="0 0 0"/>
    </visual>
    <collision>
      <geometry>
        <cylinder length="0.0000001" radius="0.0000001"/>
      </geometry>
      <origin rpy="0 0 0" xyz="0 0 0"/>
    </collision>
  </link>
  <joint name="polysat/thruster_8_joint" type="continuous">
    <origin rpy="0 0 0" xyz="0.5 0.5 0"/>
    <parent link="polysat/base_link"/>
    <child link="polysat/thruster_8"/>
    <axis xyz="1 0 0"/>
    <limit effort="0" lower="0" upper="0" velocity="0"/>
  </joint>
  <gazebo>
    <plugin filename="libsc_gazebo_thrust_plugin.so" name="polysat_8_thruster_model">
      <thruster>
        <linkName>polysat/thruster_8</linkName>
        <jointName>polysat/thruster_8_joint</jointName>
        <cmdTopic>polysat/thrusters/thruster_8</cmdTopic>
        <angleTopic>polysat/thrusters/thruster_8_angle</angleTopic>
        <enableAngle>false</enableAngle>
      </thruster>
    </plugin>
  </gazebo>
  <!-- <gazebo>
      <plugin name="${namespace}_${thruster_id}_thruster_model" filename="libLedPlugin.so">
        <light>
          <id>${namespace}/thruster_${thruster_id}/light</id>
          <block>
            <duration>1</duration>
            <interval>1</interval>
            <color>1 0.5 0.5</color>
          </block>
          <enable>true</enable>
        </light>
      </plugin>
    </gazebo> -->
  <!--gazebo reference="${namespace}/thruster_${thruster_id}">
      <xacro:led_stripe name="light_${thruster_id}" range="30" linear="0.2" constant="0.1" quadratic="0.0025"
        inner_angle="2.8" outer_angle="2.9" 
        pose="0 0 0 0 0 0"/>
    </gazebo-->
  <gazebo reference="polysat/thruster_8">
    <selfCollide>false</selfCollide>
  </gazebo>
  <link name="polysat/thruster_9">
    <inertial>
      <mass value="0.0001"/>
      <origin rpy="0 0 0" xyz="0 0 0"/>
      <inertia ixx="1.666666e-11" ixy="0.0" ixz="0.0" iyy="1.666666e-11" iyz="0.0" izz="1.666666e-11"/>
    </inertial>
    <visual>
      <geometry>
        <cylinder length="0.000001" radius="0.0000001"/>
      </geometry>
      <origin rpy="0 0 0" xyz="0 0 0"/>
    </visual>
    <collision>
      <geometry>
        <cylinder length="0.0000001" radius="0.0000001"/>
      </geometry>
      <origin rpy="0 0 0" xyz="0 0 0"/>
    </collision>
  </link>
  <joint name="polysat/thruster_9_joint" type="continuous">
    <origin rpy="0 0 0" xyz="0.5 -0.5 0"/>
    <parent link="polysat/base_link"/>
    <child link="polysat/thruster_9"/>
    <axis xyz="1 0 0"/>
    <limit effort="0" lower="0" upper="0" velocity="0"/>
  </joint>
  <gazebo>
    <plugin filename="libsc_gazebo_thrust_plugin.so" name="polysat_9_thruster_model">
      <thruster>
        <linkName>polysat/thruster_9</linkName>
        <jointName>polysat/thruster_9_joint</jointName>
        <cmdTopic>polysat/thrusters/thruster_9</cmdTopic>
        <angleTopic>polysat/thrusters/thruster_9_angle</angleTopic>
        <enableAngle>false</enableAngle>
      </thruster>
    </plugin>
  </gazebo>
  <!-- <gazebo>
      <plugin name="${namespace}_${thruster_id}_thruster_model" filename="libLedPlugin.so">
        <light>
          <id>${namespace}/thruster_${thruster_id}/light</id>
          <block>
            <duration>1</duration>
            <interval>1</interval>
            <color>1 0.5 0.5</color>
          </block>
          <enable>true</enable>
        </light>
      </plugin>
    </gazebo> -->
  <!--gazebo reference="${namespace}/thruster_${thruster_id}">
      <xacro:led_stripe name="light_${thruster_id}" range="30" linear="0.2" constant="0.1" quadratic="0.0025"
        inner_angle="2.8" outer_angle="2.9" 
        pose="0 0 0 0 0 0"/>
    </gazebo-->
  <gazebo reference="polysat/thruster_9">
    <selfCollide>false</selfCollide>
  </gazebo>
  <link name="polysat/thruster_10">
    <inertial>
      <mass value="0.0001"/>
      <origin rpy="0 0 0" xyz="0 0 0"/>
      <inertia ixx="1.666666e-11" ixy="0.0" ixz="0.0" iyy="1.666666e-11" iyz="0.0" izz="1.666666e-11"/>
    </inertial>
    <visual>
      <geometry>
        <cylinder length="0.000001" radius="0.0000001"/>
      </geometry>
      <origin rpy="0 0 0" xyz="0 0 0"/>
    </visual>
    <collision>
      <geometry>
        <cylinder length="0.0000001" radius="0.0000001"/>
      </geometry>
      <origin rpy="0 0 0" xyz="0 0 0"/>
    </collision>
  </link>
  <joint name="polysat/thruster_10_joint" type="continuous">
    <origin rpy="0 0 3.1415926535" xyz="-0.5 0.5 0"/>
    <parent link="polysat/base_link"/>
    <child link="polysat/thruster_10"/>
    <axis xyz="1 0 0"/>
    <limit effort="0" lower="0" upper="0" velocity="0"/>
  </joint>
  <gazebo>
    <plugin filename="libsc_gazebo_thrust_plugin.so" name="polysat_10_thruster_model">
      <thruster>
        <linkName>polysat/thruster_10</linkName>
        <jointName>polysat/thruster_10_joint</jointName>
        <cmdTopic>polysat/thrusters/thruster_10</cmdTopic>
        <angleTopic>polysat/thrusters/thruster_10_angle</angleTopic>
        <enableAngle>false</enableAngle>
      </thruster>
    </plugin>
  </gazebo>
  <!-- <gazebo>
      <plugin name="${namespace}_${thruster_id}_thruster_model" filename="libLedPlugin.so">
        <light>
          <id>${namespace}/thruster_${thruster_id}/light</id>
          <block>
            <duration>1</duration>
            <interval>1</interval>
            <color>1 0.5 0.5</color>
          </block>
          <enable>true</enable>
        </light>
      </plugin>
    </gazebo> -->
  <!--gazebo reference="${namespace}/thruster_${thruster_id}">
      <xacro:led_stripe name="light_${thruster_id}" range="30" linear="0.2" constant="0.1" quadratic="0.0025"
        inner_angle="2.8" outer_angle="2.9" 
        pose="0 0 0 0 0 0"/>
    </gazebo-->
  <gazebo reference="polysat/thruster_10">
    <selfCollide>false</selfCollide>
  </gazebo>
  <link name="polysat/thruster_11">
    <inertial>
      <mass value="0.0001"/>
      <origin rpy="0 0 0" xyz="0 0 0"/>
      <inertia ixx="1.666666e-11" ixy="0.0" ixz="0.0" iyy="1.666666e-11" iyz="0.0" izz="1.666666e-11"/>
    </inertial>
    <visual>
      <geometry>
        <cylinder length="0.000001" radius="0.0000001"/>
      </geometry>
      <origin rpy="0 0 0" xyz="0 0 0"/>
    </visual>
    <collision>
      <geometry>
        <cylinder length="0.0000001" radius="0.0000001"/>
      </geometry>
      <origin rpy="0 0 0" xyz="0 0 0"/>
    </collision>
  </link>
  <joint name="polysat/thruster_11_joint" type="continuous">
    <origin rpy="0 0 3.1415926535" xyz="-0.5 -0.5 0"/>
    <parent link="polysat/base_link"/>
    <child link="polysat/thruster_11"/>
    <axis xyz="1 0 0"/>
    <limit effort="0" lower="0" upper="0" velocity="0"/>
  </joint>
  <gazebo>
    <plugin filename="libsc_gazebo_thrust_plugin.so" name="polysat_11_thruster_model">
      <thruster>
        <linkName>polysat/thruster_11</linkName>
        <jointName>polysat/thruster_11_joint</jointName>
        <cmdTopic>polysat/thrusters/thruster_11</cmdTopic>
        <angleTopic>polysat/thrusters/thruster_11_angle</angleTopic>
        <enableAngle>false</enableAngle>
      </thruster>
    </plugin>
  </gazebo>
  <!-- <gazebo>
      <plugin name="${namespace}_${thruster_id}_thruster_model" filename="libLedPlugin.so">
        <light>
          <id>${namespace}/thruster_${thruster_id}/light</id>
          <block>
            <duration>1</duration>
            <interval>1</interval>
            <color>1 0.5 0.5</color>
          </block>
          <enable>true</enable>
        </light>
      </plugin>
    </gazebo> -->
  <!--gazebo reference="${namespace}/thruster_${thruster_id}">
      <xacro:led_stripe name="light_${thruster_id}" range="30" linear="0.2" constant="0.1" quadratic="0.0025"
        inner_angle="2.8" outer_angle="2.9" 
        pose="0 0 0 0 0 0"/>
    </gazebo-->
  <gazebo reference="polysat/thruster_11">
    <selfCollide>false</selfCollide>
  </gazebo>
  <link name="polysat/thruster_12">
    <inertial>
      <mass value="0.0001"/>
      <origin rpy="0 0 0" xyz="0 0 0"/>
      <inertia ixx="1.666666e-11" ixy="0.0" ixz="0.0" iyy="1.666666e-11" iyz="0.0" izz="1.666666e-11"/>
    </inertial>
    <visual>
      <geometry>
        <cylinder length="0.000001" radius="0.0000001"/>
      </geometry>
      <origin rpy="0 0 0" xyz="0 0 0"/>
    </visual>
    <collision>
      <geometry>
        <cylinder length="0.0000001" radius="0.0000001"/>
      </geometry>
      <origin rpy="0 0 0" xyz="0 0 0"/>
    </collision>
  </link>
  <joint name="polysat/thruster_12_joint" type="continuous">
    <origin rpy="0 0 1.5707963268" xyz="0 0.5 0"/>
    <parent link="polysat/base_link"/>
    <child link="polysat/thruster_12"/>
    <axis xyz="1 0 0"/>
    <limit effort="0" lower="0" upper="0" velocity="0"/>
  </joint>
  <gazebo>
    <plugin filename="libsc_gazebo_thrust_plugin.so" name="polysat_12_thruster_model">
      <thruster>
        <linkName>polysat/thruster_12</linkName>
        <jointName>polysat/thruster_12_joint</jointName>
        <cmdTopic>polysat/thrusters/thruster_12</cmdTopic>
        <angleTopic>polysat/thrusters/thruster_12_angle</angleTopic>
        <enableAngle>false</enableAngle>
      </thruster>
    </plugin>
  </gazebo>
  <!-- <gazebo>
      <plugin name="${namespace}_${thruster_id}_thruster_model" filename="libLedPlugin.so">
        <light>
          <id>${namespace}/thruster_${thruster_id}/light</id>
          <block>
            <duration>1</duration>
            <interval>1</interval>
            <color>1 0.5 0.5</color>
          </block>
          <enable>true</enable>
        </light>
      </plugin>
    </gazebo> -->
  <!--gazebo reference="${namespace}/thruster_${thruster_id}">
      <xacro:led_stripe name="light_${thruster_id}" range="30" linear="0.2" constant="0.1" quadratic="0.0025"
        inner_angle="2.8" outer_angle="2.9" 
        pose="0 0 0 0 0 0"/>
    </gazebo-->
  <gazebo reference="polysat/thruster_12">
    <selfCollide>false</selfCollide>
  </gazebo>
  <link name="polysat/thruster_13">
    <inertial>
      <mass value="0.0001"/>
      <origin rpy="0 0 0" xyz="0 0 0"/>
      <inertia ixx="1.666666e-11" ixy="0.0" ixz="0.0" iyy="1.666666e-11" iyz="0.0" izz="1.666666e-11"/>
    </inertial>
    <visual>
      <geometry>
        <cylinder length="0.000001" radius="0.0000001"/>
      </geometry>
      <origin rpy="0 0 0" xyz="0 0 0"/>
    </visual>
    <collision>
      <geometry>
        <cylinder length="0.0000001" radius="0.0000001"/>
      </geometry>
      <origin rpy="0 0 0" xyz="0 0 0"/>
    </collision>
  </link>
  <joint name="polysat/thruster_13_joint" type="continuous">
    <origin rpy="0 0 -1.5707963268" xyz="0 -0.5 0"/>
    <parent link="polysat/base_link"/>
    <child link="polysat/thruster_13"/>
    <axis xyz="1 0 0"/>
    <limit effort="0" lower="0" upper="0" velocity="0"/>
  </joint>
  <gazebo>
    <plugin filename="libsc_gazebo_thrust_plugin.so" name="polysat_13_thruster_model">
      <thruster>
        <linkName>polysat/thruster_13</linkName>
        <jointName>polysat/thruster_13_joint</jointName>
        <cmdTopic>polysat/thrusters/thruster_13</cmdTopic>
        <angleTopic>polysat/thrusters/thruster_13_angle</angleTopic>
        <enableAngle>false</enableAngle>
      </thruster>
    </plugin>
  </gazebo>
  <!-- <gazebo>
      <plugin name="${namespace}_${thruster_id}_thruster_model" filename="libLedPlugin.so">
        <light>
          <id>${namespace}/thruster_${thruster_id}/light</id>
          <block>
            <duration>1</duration>
            <interval>1</interval>
            <color>1 0.5 0.5</color>
          </block>
          <enable>true</enable>
        </light>
      </plugin>
    </gazebo> -->
  <!--gazebo reference="${namespace}/thruster_${thruster_id}">
      <xacro:led_stripe name="light_${thruster_id}" range="30" linear="0.2" constant="0.1" quadratic="0.0025"
        inner_angle="2.8" outer_angle="2.9" 
        pose="0 0 0 0 0 0"/>
    </gazebo-->
  <gazebo reference="polysat/thruster_13">
    <selfCollide>false</selfCollide>
  </gazebo>
  <!-- IMU link -->
  <link name="polysat/imu_link">
    <inertial>
      <inertia ixx="0.00001" ixy="0.0" ixz="0.0" iyy="0.00001" iyz="0.0" izz="0.00001"/>
      <mass value="0.015"/>
      <!-- [kg] -->
      <origin rpy="0 0 0" xyz="0 0 0"/>
    </inertial>
  </link>
  <!-- IMU joint -->
  <joint name="polysat/imu_joint" type="revolute">
    <origin rpy="0 0 0" xyz="0 0 0"/>
    <parent link="polysat/base_link"/>
    <child link="polysat/imu_link"/>
    <limit effort="0" lower="0" upper="0" velocity="0"/>
    <axis xyz="1 0 0"/>
  </joint>
  <gazebo>
    <plugin filename="libsc_imu_gazebo_plugin.so" name="libsc_imu_gazebo_plugin">
      <!-- A good description of the IMU parameters can be found in the kalibr documentation:
           https://github.com/ethz-asl/kalibr/wiki/IMU-Noise-Model-and-Intrinsics -->
      <robot_namespace>polysat</robot_namespace>
      <!-- (string, required): ros namespace in which the messages are published -->
      <link_name>polysat/imu_link</link_name>
      <!-- (string, required): name of the body which holds the IMU sensor -->
      <sensor_topic>imu</sensor_topic>
      <!-- (string): name of the sensor output topic and prefix of service names (defaults to imu) -->
      <gyroscope_noise_density>0.0003394</gyroscope_noise_density>
      <!-- Gyroscope noise density (two-sided spectrum) [rad/s/sqrt(Hz)] -->
      <gyroscope_random_walk>3.8785e-05</gyroscope_random_walk>
      <!-- Gyroscope bias random walk [rad/s/s/sqrt(Hz)] -->
      <gyroscope_bias_correlation_time>1000.0</gyroscope_bias_correlation_time>
      <!-- Gyroscope bias correlation time constant [s] -->
      <gyroscope_turn_on_bias_sigma>0.0087</gyroscope_turn_on_bias_sigma>
      <!-- Gyroscope turn on bias standard deviation [rad/s] -->
      <accelerometer_noise_density>0.004</accelerometer_noise_density>
      <!-- Accelerometer noise density (two-sided spectrum) [m/s^2/sqrt(Hz)] -->
      <accelerometer_random_walk>0.006</accelerometer_random_walk>
      <!-- Accelerometer bias random walk. [m/s^2/s/sqrt(Hz)] -->
      <accelerometer_bias_correlation_time>300.0</accelerometer_bias_correlation_time>
      <!-- Accelerometer bias correlation time constant [s] -->
      <accelerometer_turn_on_bias_sigma>0.196</accelerometer_turn_on_bias_sigma>
      <!-- Accelerometer turn on bias standard deviation [m/s^2] -->
      <orientation_noise>0.01</orientation_noise>
      <update_rate>50</update_rate>
      <!-- Update period of accelerometer and gyroscope [s] -->
      <enable_gazebo_messages>false</enable_gazebo_messages>
      <enable_local_ned_frame>False</enable_local_ned_frame>
      <static_reference_frame>world</static_reference_frame>
    </plugin>
  </gazebo>
  <!--Mount a 3D pose sensor-->
  <link name="polysat/pose_sensor_link_default">
    <inertial>
      <inertia ixx="0.00001" ixy="0.0" ixz="0.0" iyy="0.00001" iyz="0.0" izz="0.00001"/>
      <mass value="0.001"/>
      <origin rpy="0 0 0" xyz="0 0 0"/>
    </inertial>
  </link>
  <joint name="polysat/pose_sensor_default_joint" type="revolute">
    <origin rpy="0 0 0" xyz="0 0 0"/>
    <axis xyz="0 0 1"/>
    <parent link="polysat/base_link"/>
    <child link="polysat/pose_sensor_link_default"/>
    <limit effort="0" lower="0" upper="0" velocity="0"/>
  </joint>
  <gazebo>
    <plugin filename="libsc_pose_gt_plugin.so" name="pose_3d_plugin">
      <robot_namespace>polysat</robot_namespace>
      <link_name>polysat/base_link</link_name>
      <sensor_topic>pose_gt</sensor_topic>
      <static_reference_frame>world</static_reference_frame>
      <noise_sigma>0.0</noise_sigma>
      <noise_amplitude>0.0</noise_amplitude>
      <update_rate>20</update_rate>
      <enable_gazebo_messages>false</enable_gazebo_messages>
      <publish_ned_odom>False</publish_ned_odom>
    </plugin>
  </gazebo>
  <!--xacro:include filename="$(find polysat_description)/urdf/polysat_sensors.xacro"/-->
  <!--
  <xacro:oberon7_arm transmission_hw_interface="$(arg transmission_hw_interface)" namespace="oberon7_r"/>
  <xacro:oberon7_arm transmission_hw_interface="$(arg transmission_hw_interface)" namespace="oberon7_l"/>

  <joint name="oberon7_r_anchor" type="fixed">
    <parent link="$(arg namespace)/base_link"/>
    <child link="oberon7_r/base"/>
    <origin rpy="-1.5707963268 0 0" xyz="0 1.5 0"/>
  </joint>
  <joint name="oberon7_l_anchor" type="fixed">
    <parent link="$(arg namespace)/base_link"/>
    <child link="oberon7_l/base"/>
    <origin rpy="1.5707963268 0 0" xyz="0 -1.5 0"/>
  </joint>
  -->
</robot>

